[2018-09-19 12:16:48,199] ERROR in app: Exception on / [GET]
Traceback (most recent call last):
  File "/home/lya/doc/new_flasky/venv/lib/python3.6/site-packages/flask/app.py", line 2292, in wsgi_app
    response = self.full_dispatch_request()
  File "/home/lya/doc/new_flasky/venv/lib/python3.6/site-packages/flask/app.py", line 1815, in full_dispatch_request
    rv = self.handle_user_exception(e)
  File "/home/lya/doc/new_flasky/venv/lib/python3.6/site-packages/flask/app.py", line 1718, in handle_user_exception
    reraise(exc_type, exc_value, tb)
  File "/home/lya/doc/new_flasky/venv/lib/python3.6/site-packages/flask/_compat.py", line 35, in reraise
    raise value
  File "/home/lya/doc/new_flasky/venv/lib/python3.6/site-packages/flask/app.py", line 1813, in full_dispatch_request
    rv = self.dispatch_request()
  File "/home/lya/doc/new_flasky/venv/lib/python3.6/site-packages/flask/app.py", line 1799, in dispatch_request
    return self.view_functions[rule.endpoint](**req.view_args)
  File "/home/lya/doc/new_flasky/app/main/views.py", line 53, in index
    show_followed=show_followed, pagination=pagination)
  File "/home/lya/doc/new_flasky/venv/lib/python3.6/site-packages/flask/templating.py", line 133, in render_template
    ctx.app.update_template_context(context)
  File "/home/lya/doc/new_flasky/venv/lib/python3.6/site-packages/flask/app.py", line 792, in update_template_context
    context.update(func())
  File "/home/lya/doc/new_flasky/app/main/__init__.py", line 20, in inject_permissions
    greater_users=int(generate_greater_users()))
  File "/home/lya/doc/new_flasky/app/main/__init__.py", line 12, in generate_greater_users
    if int(curr) - 1 > int(greater):
TypeError: int() argument must be a string, a bytes-like object or a number, not 'NoneType'
[2018-09-19 12:16:48,562] ERROR in app: Exception on /favicon.ico [GET]
Traceback (most recent call last):
  File "/home/lya/doc/new_flasky/venv/lib/python3.6/site-packages/flask/app.py", line 1813, in full_dispatch_request
    rv = self.dispatch_request()
  File "/home/lya/doc/new_flasky/venv/lib/python3.6/site-packages/flask/app.py", line 1791, in dispatch_request
    self.raise_routing_exception(req)
  File "/home/lya/doc/new_flasky/venv/lib/python3.6/site-packages/flask/app.py", line 1774, in raise_routing_exception
    raise request.routing_exception
  File "/home/lya/doc/new_flasky/venv/lib/python3.6/site-packages/flask/ctx.py", line 336, in match_request
    self.url_adapter.match(return_rule=True)
  File "/home/lya/doc/new_flasky/venv/lib/python3.6/site-packages/werkzeug/routing.py", line 1581, in match
    raise NotFound()
werkzeug.exceptions.NotFound: 404 Not Found: The requested URL was not found on the server.  If you entered the URL manually please check your spelling and try again.

During handling of the above exception, another exception occurred:

Traceback (most recent call last):
  File "/home/lya/doc/new_flasky/venv/lib/python3.6/site-packages/flask/app.py", line 2292, in wsgi_app
    response = self.full_dispatch_request()
  File "/home/lya/doc/new_flasky/venv/lib/python3.6/site-packages/flask/app.py", line 1815, in full_dispatch_request
    rv = self.handle_user_exception(e)
  File "/home/lya/doc/new_flasky/venv/lib/python3.6/site-packages/flask/app.py", line 1713, in handle_user_exception
    return self.handle_http_exception(e)
  File "/home/lya/doc/new_flasky/venv/lib/python3.6/site-packages/flask/app.py", line 1644, in handle_http_exception
    return handler(e)
  File "/home/lya/doc/new_flasky/app/main/errors.py", line 16, in page_not_found
    return render_template('404.html'), 404
  File "/home/lya/doc/new_flasky/venv/lib/python3.6/site-packages/flask/templating.py", line 133, in render_template
    ctx.app.update_template_context(context)
  File "/home/lya/doc/new_flasky/venv/lib/python3.6/site-packages/flask/app.py", line 792, in update_template_context
    context.update(func())
  File "/home/lya/doc/new_flasky/app/main/__init__.py", line 20, in inject_permissions
    greater_users=int(generate_greater_users()))
  File "/home/lya/doc/new_flasky/app/main/__init__.py", line 12, in generate_greater_users
    if int(curr) - 1 > int(greater):
TypeError: int() argument must be a string, a bytes-like object or a number, not 'NoneType'
[2018-09-19 12:52:24,184] ERROR in app: Exception on / [GET]
Traceback (most recent call last):
  File "/home/lya/doc/new_flasky/venv/lib/python3.6/site-packages/flask/app.py", line 2292, in wsgi_app
    response = self.full_dispatch_request()
  File "/home/lya/doc/new_flasky/venv/lib/python3.6/site-packages/flask/app.py", line 1815, in full_dispatch_request
    rv = self.handle_user_exception(e)
  File "/home/lya/doc/new_flasky/venv/lib/python3.6/site-packages/flask/app.py", line 1718, in handle_user_exception
    reraise(exc_type, exc_value, tb)
  File "/home/lya/doc/new_flasky/venv/lib/python3.6/site-packages/flask/_compat.py", line 35, in reraise
    raise value
  File "/home/lya/doc/new_flasky/venv/lib/python3.6/site-packages/flask/app.py", line 1813, in full_dispatch_request
    rv = self.dispatch_request()
  File "/home/lya/doc/new_flasky/venv/lib/python3.6/site-packages/flask/app.py", line 1799, in dispatch_request
    return self.view_functions[rule.endpoint](**req.view_args)
  File "/home/lya/doc/new_flasky/app/main/views.py", line 53, in index
    show_followed=show_followed, pagination=pagination)
  File "/home/lya/doc/new_flasky/venv/lib/python3.6/site-packages/flask/templating.py", line 133, in render_template
    ctx.app.update_template_context(context)
  File "/home/lya/doc/new_flasky/venv/lib/python3.6/site-packages/flask/app.py", line 792, in update_template_context
    context.update(func())
  File "/home/lya/doc/new_flasky/app/main/__init__.py", line 20, in inject_permissions
    greater_users=int(generate_greater_users()))
  File "/home/lya/doc/new_flasky/app/main/__init__.py", line 12, in generate_greater_users
    if int(curr) - 1 > int(greater):
TypeError: int() argument must be a string, a bytes-like object or a number, not 'NoneType'
[2018-09-19 12:52:24,951] ERROR in app: Exception on /favicon.ico [GET]
Traceback (most recent call last):
  File "/home/lya/doc/new_flasky/venv/lib/python3.6/site-packages/flask/app.py", line 1813, in full_dispatch_request
    rv = self.dispatch_request()
  File "/home/lya/doc/new_flasky/venv/lib/python3.6/site-packages/flask/app.py", line 1791, in dispatch_request
    self.raise_routing_exception(req)
  File "/home/lya/doc/new_flasky/venv/lib/python3.6/site-packages/flask/app.py", line 1774, in raise_routing_exception
    raise request.routing_exception
  File "/home/lya/doc/new_flasky/venv/lib/python3.6/site-packages/flask/ctx.py", line 336, in match_request
    self.url_adapter.match(return_rule=True)
  File "/home/lya/doc/new_flasky/venv/lib/python3.6/site-packages/werkzeug/routing.py", line 1581, in match
    raise NotFound()
werkzeug.exceptions.NotFound: 404 Not Found: The requested URL was not found on the server.  If you entered the URL manually please check your spelling and try again.

During handling of the above exception, another exception occurred:

Traceback (most recent call last):
  File "/home/lya/doc/new_flasky/venv/lib/python3.6/site-packages/flask/app.py", line 2292, in wsgi_app
    response = self.full_dispatch_request()
  File "/home/lya/doc/new_flasky/venv/lib/python3.6/site-packages/flask/app.py", line 1815, in full_dispatch_request
    rv = self.handle_user_exception(e)
  File "/home/lya/doc/new_flasky/venv/lib/python3.6/site-packages/flask/app.py", line 1713, in handle_user_exception
    return self.handle_http_exception(e)
  File "/home/lya/doc/new_flasky/venv/lib/python3.6/site-packages/flask/app.py", line 1644, in handle_http_exception
    return handler(e)
  File "/home/lya/doc/new_flasky/app/main/errors.py", line 16, in page_not_found
    return render_template('404.html'), 404
  File "/home/lya/doc/new_flasky/venv/lib/python3.6/site-packages/flask/templating.py", line 133, in render_template
    ctx.app.update_template_context(context)
  File "/home/lya/doc/new_flasky/venv/lib/python3.6/site-packages/flask/app.py", line 792, in update_template_context
    context.update(func())
  File "/home/lya/doc/new_flasky/app/main/__init__.py", line 20, in inject_permissions
    greater_users=int(generate_greater_users()))
  File "/home/lya/doc/new_flasky/app/main/__init__.py", line 12, in generate_greater_users
    if int(curr) - 1 > int(greater):
TypeError: int() argument must be a string, a bytes-like object or a number, not 'NoneType'
[2018-09-19 12:52:58,835] ERROR in app: Exception on / [GET]
Traceback (most recent call last):
  File "/home/lya/doc/new_flasky/venv/lib/python3.6/site-packages/flask/app.py", line 2292, in wsgi_app
    response = self.full_dispatch_request()
  File "/home/lya/doc/new_flasky/venv/lib/python3.6/site-packages/flask/app.py", line 1815, in full_dispatch_request
    rv = self.handle_user_exception(e)
  File "/home/lya/doc/new_flasky/venv/lib/python3.6/site-packages/flask/app.py", line 1718, in handle_user_exception
    reraise(exc_type, exc_value, tb)
  File "/home/lya/doc/new_flasky/venv/lib/python3.6/site-packages/flask/_compat.py", line 35, in reraise
    raise value
  File "/home/lya/doc/new_flasky/venv/lib/python3.6/site-packages/flask/app.py", line 1813, in full_dispatch_request
    rv = self.dispatch_request()
  File "/home/lya/doc/new_flasky/venv/lib/python3.6/site-packages/flask/app.py", line 1799, in dispatch_request
    return self.view_functions[rule.endpoint](**req.view_args)
  File "/home/lya/doc/new_flasky/app/main/views.py", line 53, in index
    show_followed=show_followed, pagination=pagination)
  File "/home/lya/doc/new_flasky/venv/lib/python3.6/site-packages/flask/templating.py", line 133, in render_template
    ctx.app.update_template_context(context)
  File "/home/lya/doc/new_flasky/venv/lib/python3.6/site-packages/flask/app.py", line 792, in update_template_context
    context.update(func())
  File "/home/lya/doc/new_flasky/app/main/__init__.py", line 20, in inject_permissions
    greater_users=int(generate_greater_users()))
  File "/home/lya/doc/new_flasky/app/main/__init__.py", line 12, in generate_greater_users
    if int(curr) - 1 > int(greater):
TypeError: int() argument must be a string, a bytes-like object or a number, not 'NoneType'
[2018-09-19 12:52:59,257] ERROR in app: Exception on /favicon.ico [GET]
Traceback (most recent call last):
  File "/home/lya/doc/new_flasky/venv/lib/python3.6/site-packages/flask/app.py", line 1813, in full_dispatch_request
    rv = self.dispatch_request()
  File "/home/lya/doc/new_flasky/venv/lib/python3.6/site-packages/flask/app.py", line 1791, in dispatch_request
    self.raise_routing_exception(req)
  File "/home/lya/doc/new_flasky/venv/lib/python3.6/site-packages/flask/app.py", line 1774, in raise_routing_exception
    raise request.routing_exception
  File "/home/lya/doc/new_flasky/venv/lib/python3.6/site-packages/flask/ctx.py", line 336, in match_request
    self.url_adapter.match(return_rule=True)
  File "/home/lya/doc/new_flasky/venv/lib/python3.6/site-packages/werkzeug/routing.py", line 1581, in match
    raise NotFound()
werkzeug.exceptions.NotFound: 404 Not Found: The requested URL was not found on the server.  If you entered the URL manually please check your spelling and try again.

During handling of the above exception, another exception occurred:

Traceback (most recent call last):
  File "/home/lya/doc/new_flasky/venv/lib/python3.6/site-packages/flask/app.py", line 2292, in wsgi_app
    response = self.full_dispatch_request()
  File "/home/lya/doc/new_flasky/venv/lib/python3.6/site-packages/flask/app.py", line 1815, in full_dispatch_request
    rv = self.handle_user_exception(e)
  File "/home/lya/doc/new_flasky/venv/lib/python3.6/site-packages/flask/app.py", line 1713, in handle_user_exception
    return self.handle_http_exception(e)
  File "/home/lya/doc/new_flasky/venv/lib/python3.6/site-packages/flask/app.py", line 1644, in handle_http_exception
    return handler(e)
  File "/home/lya/doc/new_flasky/app/main/errors.py", line 16, in page_not_found
    return render_template('404.html'), 404
  File "/home/lya/doc/new_flasky/venv/lib/python3.6/site-packages/flask/templating.py", line 133, in render_template
    ctx.app.update_template_context(context)
  File "/home/lya/doc/new_flasky/venv/lib/python3.6/site-packages/flask/app.py", line 792, in update_template_context
    context.update(func())
  File "/home/lya/doc/new_flasky/app/main/__init__.py", line 20, in inject_permissions
    greater_users=int(generate_greater_users()))
  File "/home/lya/doc/new_flasky/app/main/__init__.py", line 12, in generate_greater_users
    if int(curr) - 1 > int(greater):
TypeError: int() argument must be a string, a bytes-like object or a number, not 'NoneType'
[2018-09-19 12:54:08,092] ERROR in app: Exception on / [GET]
Traceback (most recent call last):
  File "/home/lya/doc/new_flasky/venv/lib/python3.6/site-packages/flask/app.py", line 2292, in wsgi_app
    response = self.full_dispatch_request()
  File "/home/lya/doc/new_flasky/venv/lib/python3.6/site-packages/flask/app.py", line 1815, in full_dispatch_request
    rv = self.handle_user_exception(e)
  File "/home/lya/doc/new_flasky/venv/lib/python3.6/site-packages/flask/app.py", line 1718, in handle_user_exception
    reraise(exc_type, exc_value, tb)
  File "/home/lya/doc/new_flasky/venv/lib/python3.6/site-packages/flask/_compat.py", line 35, in reraise
    raise value
  File "/home/lya/doc/new_flasky/venv/lib/python3.6/site-packages/flask/app.py", line 1813, in full_dispatch_request
    rv = self.dispatch_request()
  File "/home/lya/doc/new_flasky/venv/lib/python3.6/site-packages/flask/app.py", line 1799, in dispatch_request
    return self.view_functions[rule.endpoint](**req.view_args)
  File "/home/lya/doc/new_flasky/app/main/views.py", line 53, in index
    show_followed=show_followed, pagination=pagination)
  File "/home/lya/doc/new_flasky/venv/lib/python3.6/site-packages/flask/templating.py", line 133, in render_template
    ctx.app.update_template_context(context)
  File "/home/lya/doc/new_flasky/venv/lib/python3.6/site-packages/flask/app.py", line 792, in update_template_context
    context.update(func())
  File "/home/lya/doc/new_flasky/app/main/__init__.py", line 20, in inject_permissions
    greater_users=int(generate_greater_users()))
  File "/home/lya/doc/new_flasky/app/main/__init__.py", line 12, in generate_greater_users
    if int(curr) - 1 > int(greater):
TypeError: int() argument must be a string, a bytes-like object or a number, not 'NoneType'
[2018-09-19 12:54:08,704] ERROR in app: Exception on /favicon.ico [GET]
Traceback (most recent call last):
  File "/home/lya/doc/new_flasky/venv/lib/python3.6/site-packages/flask/app.py", line 1813, in full_dispatch_request
    rv = self.dispatch_request()
  File "/home/lya/doc/new_flasky/venv/lib/python3.6/site-packages/flask/app.py", line 1791, in dispatch_request
    self.raise_routing_exception(req)
  File "/home/lya/doc/new_flasky/venv/lib/python3.6/site-packages/flask/app.py", line 1774, in raise_routing_exception
    raise request.routing_exception
  File "/home/lya/doc/new_flasky/venv/lib/python3.6/site-packages/flask/ctx.py", line 336, in match_request
    self.url_adapter.match(return_rule=True)
  File "/home/lya/doc/new_flasky/venv/lib/python3.6/site-packages/werkzeug/routing.py", line 1581, in match
    raise NotFound()
werkzeug.exceptions.NotFound: 404 Not Found: The requested URL was not found on the server.  If you entered the URL manually please check your spelling and try again.

During handling of the above exception, another exception occurred:

Traceback (most recent call last):
  File "/home/lya/doc/new_flasky/venv/lib/python3.6/site-packages/flask/app.py", line 2292, in wsgi_app
    response = self.full_dispatch_request()
  File "/home/lya/doc/new_flasky/venv/lib/python3.6/site-packages/flask/app.py", line 1815, in full_dispatch_request
    rv = self.handle_user_exception(e)
  File "/home/lya/doc/new_flasky/venv/lib/python3.6/site-packages/flask/app.py", line 1713, in handle_user_exception
    return self.handle_http_exception(e)
  File "/home/lya/doc/new_flasky/venv/lib/python3.6/site-packages/flask/app.py", line 1644, in handle_http_exception
    return handler(e)
  File "/home/lya/doc/new_flasky/app/main/errors.py", line 16, in page_not_found
    return render_template('404.html'), 404
  File "/home/lya/doc/new_flasky/venv/lib/python3.6/site-packages/flask/templating.py", line 133, in render_template
    ctx.app.update_template_context(context)
  File "/home/lya/doc/new_flasky/venv/lib/python3.6/site-packages/flask/app.py", line 792, in update_template_context
    context.update(func())
  File "/home/lya/doc/new_flasky/app/main/__init__.py", line 20, in inject_permissions
    greater_users=int(generate_greater_users()))
  File "/home/lya/doc/new_flasky/app/main/__init__.py", line 12, in generate_greater_users
    if int(curr) - 1 > int(greater):
TypeError: int() argument must be a string, a bytes-like object or a number, not 'NoneType'
[2018-09-19 12:55:42,327] ERROR in app: Exception on / [GET]
Traceback (most recent call last):
  File "/home/lya/doc/new_flasky/venv/lib/python3.6/site-packages/flask/app.py", line 2292, in wsgi_app
    response = self.full_dispatch_request()
  File "/home/lya/doc/new_flasky/venv/lib/python3.6/site-packages/flask/app.py", line 1815, in full_dispatch_request
    rv = self.handle_user_exception(e)
  File "/home/lya/doc/new_flasky/venv/lib/python3.6/site-packages/flask/app.py", line 1718, in handle_user_exception
    reraise(exc_type, exc_value, tb)
  File "/home/lya/doc/new_flasky/venv/lib/python3.6/site-packages/flask/_compat.py", line 35, in reraise
    raise value
  File "/home/lya/doc/new_flasky/venv/lib/python3.6/site-packages/flask/app.py", line 1813, in full_dispatch_request
    rv = self.dispatch_request()
  File "/home/lya/doc/new_flasky/venv/lib/python3.6/site-packages/flask/app.py", line 1799, in dispatch_request
    return self.view_functions[rule.endpoint](**req.view_args)
  File "/home/lya/doc/new_flasky/app/main/views.py", line 53, in index
    show_followed=show_followed, pagination=pagination)
  File "/home/lya/doc/new_flasky/venv/lib/python3.6/site-packages/flask/templating.py", line 133, in render_template
    ctx.app.update_template_context(context)
  File "/home/lya/doc/new_flasky/venv/lib/python3.6/site-packages/flask/app.py", line 792, in update_template_context
    context.update(func())
  File "/home/lya/doc/new_flasky/app/main/__init__.py", line 20, in inject_permissions
    greater_users=int(generate_greater_users()))
  File "/home/lya/doc/new_flasky/app/main/__init__.py", line 12, in generate_greater_users
    if int(curr) - 1 > int(greater):
TypeError: int() argument must be a string, a bytes-like object or a number, not 'NoneType'
[2018-09-19 12:55:42,867] ERROR in app: Exception on /favicon.ico [GET]
Traceback (most recent call last):
  File "/home/lya/doc/new_flasky/venv/lib/python3.6/site-packages/flask/app.py", line 1813, in full_dispatch_request
    rv = self.dispatch_request()
  File "/home/lya/doc/new_flasky/venv/lib/python3.6/site-packages/flask/app.py", line 1791, in dispatch_request
    self.raise_routing_exception(req)
  File "/home/lya/doc/new_flasky/venv/lib/python3.6/site-packages/flask/app.py", line 1774, in raise_routing_exception
    raise request.routing_exception
  File "/home/lya/doc/new_flasky/venv/lib/python3.6/site-packages/flask/ctx.py", line 336, in match_request
    self.url_adapter.match(return_rule=True)
  File "/home/lya/doc/new_flasky/venv/lib/python3.6/site-packages/werkzeug/routing.py", line 1581, in match
    raise NotFound()
werkzeug.exceptions.NotFound: 404 Not Found: The requested URL was not found on the server.  If you entered the URL manually please check your spelling and try again.

During handling of the above exception, another exception occurred:

Traceback (most recent call last):
  File "/home/lya/doc/new_flasky/venv/lib/python3.6/site-packages/flask/app.py", line 2292, in wsgi_app
    response = self.full_dispatch_request()
  File "/home/lya/doc/new_flasky/venv/lib/python3.6/site-packages/flask/app.py", line 1815, in full_dispatch_request
    rv = self.handle_user_exception(e)
  File "/home/lya/doc/new_flasky/venv/lib/python3.6/site-packages/flask/app.py", line 1713, in handle_user_exception
    return self.handle_http_exception(e)
  File "/home/lya/doc/new_flasky/venv/lib/python3.6/site-packages/flask/app.py", line 1644, in handle_http_exception
    return handler(e)
  File "/home/lya/doc/new_flasky/app/main/errors.py", line 16, in page_not_found
    return render_template('404.html'), 404
  File "/home/lya/doc/new_flasky/venv/lib/python3.6/site-packages/flask/templating.py", line 133, in render_template
    ctx.app.update_template_context(context)
  File "/home/lya/doc/new_flasky/venv/lib/python3.6/site-packages/flask/app.py", line 792, in update_template_context
    context.update(func())
  File "/home/lya/doc/new_flasky/app/main/__init__.py", line 20, in inject_permissions
    greater_users=int(generate_greater_users()))
  File "/home/lya/doc/new_flasky/app/main/__init__.py", line 12, in generate_greater_users
    if int(curr) - 1 > int(greater):
TypeError: int() argument must be a string, a bytes-like object or a number, not 'NoneType'
[2018-09-19 12:57:02,679] ERROR in app: Exception on / [GET]
Traceback (most recent call last):
  File "/home/lya/doc/new_flasky/venv/lib/python3.6/site-packages/flask/app.py", line 2292, in wsgi_app
    response = self.full_dispatch_request()
  File "/home/lya/doc/new_flasky/venv/lib/python3.6/site-packages/flask/app.py", line 1815, in full_dispatch_request
    rv = self.handle_user_exception(e)
  File "/home/lya/doc/new_flasky/venv/lib/python3.6/site-packages/flask/app.py", line 1718, in handle_user_exception
    reraise(exc_type, exc_value, tb)
  File "/home/lya/doc/new_flasky/venv/lib/python3.6/site-packages/flask/_compat.py", line 35, in reraise
    raise value
  File "/home/lya/doc/new_flasky/venv/lib/python3.6/site-packages/flask/app.py", line 1813, in full_dispatch_request
    rv = self.dispatch_request()
  File "/home/lya/doc/new_flasky/venv/lib/python3.6/site-packages/flask/app.py", line 1799, in dispatch_request
    return self.view_functions[rule.endpoint](**req.view_args)
  File "/home/lya/doc/new_flasky/app/main/views.py", line 53, in index
    show_followed=show_followed, pagination=pagination)
  File "/home/lya/doc/new_flasky/venv/lib/python3.6/site-packages/flask/templating.py", line 133, in render_template
    ctx.app.update_template_context(context)
  File "/home/lya/doc/new_flasky/venv/lib/python3.6/site-packages/flask/app.py", line 792, in update_template_context
    context.update(func())
  File "/home/lya/doc/new_flasky/app/main/__init__.py", line 20, in inject_permissions
    greater_users=int(generate_greater_users()))
  File "/home/lya/doc/new_flasky/app/main/__init__.py", line 12, in generate_greater_users
    if int(curr) - 1 > int(greater):
TypeError: int() argument must be a string, a bytes-like object or a number, not 'NoneType'
[2018-09-19 12:57:03,255] ERROR in app: Exception on /favicon.ico [GET]
Traceback (most recent call last):
  File "/home/lya/doc/new_flasky/venv/lib/python3.6/site-packages/flask/app.py", line 1813, in full_dispatch_request
    rv = self.dispatch_request()
  File "/home/lya/doc/new_flasky/venv/lib/python3.6/site-packages/flask/app.py", line 1791, in dispatch_request
    self.raise_routing_exception(req)
  File "/home/lya/doc/new_flasky/venv/lib/python3.6/site-packages/flask/app.py", line 1774, in raise_routing_exception
    raise request.routing_exception
  File "/home/lya/doc/new_flasky/venv/lib/python3.6/site-packages/flask/ctx.py", line 336, in match_request
    self.url_adapter.match(return_rule=True)
  File "/home/lya/doc/new_flasky/venv/lib/python3.6/site-packages/werkzeug/routing.py", line 1581, in match
    raise NotFound()
werkzeug.exceptions.NotFound: 404 Not Found: The requested URL was not found on the server.  If you entered the URL manually please check your spelling and try again.

During handling of the above exception, another exception occurred:

Traceback (most recent call last):
  File "/home/lya/doc/new_flasky/venv/lib/python3.6/site-packages/flask/app.py", line 2292, in wsgi_app
    response = self.full_dispatch_request()
  File "/home/lya/doc/new_flasky/venv/lib/python3.6/site-packages/flask/app.py", line 1815, in full_dispatch_request
    rv = self.handle_user_exception(e)
  File "/home/lya/doc/new_flasky/venv/lib/python3.6/site-packages/flask/app.py", line 1713, in handle_user_exception
    return self.handle_http_exception(e)
  File "/home/lya/doc/new_flasky/venv/lib/python3.6/site-packages/flask/app.py", line 1644, in handle_http_exception
    return handler(e)
  File "/home/lya/doc/new_flasky/app/main/errors.py", line 16, in page_not_found
    return render_template('404.html'), 404
  File "/home/lya/doc/new_flasky/venv/lib/python3.6/site-packages/flask/templating.py", line 133, in render_template
    ctx.app.update_template_context(context)
  File "/home/lya/doc/new_flasky/venv/lib/python3.6/site-packages/flask/app.py", line 792, in update_template_context
    context.update(func())
  File "/home/lya/doc/new_flasky/app/main/__init__.py", line 20, in inject_permissions
    greater_users=int(generate_greater_users()))
  File "/home/lya/doc/new_flasky/app/main/__init__.py", line 12, in generate_greater_users
    if int(curr) - 1 > int(greater):
TypeError: int() argument must be a string, a bytes-like object or a number, not 'NoneType'
[2018-09-19 13:02:31,214] ERROR in app: Exception on / [GET]
Traceback (most recent call last):
  File "/home/lya/doc/new_flasky/venv/lib/python3.6/site-packages/flask/app.py", line 2292, in wsgi_app
    response = self.full_dispatch_request()
  File "/home/lya/doc/new_flasky/venv/lib/python3.6/site-packages/flask/app.py", line 1815, in full_dispatch_request
    rv = self.handle_user_exception(e)
  File "/home/lya/doc/new_flasky/venv/lib/python3.6/site-packages/flask/app.py", line 1718, in handle_user_exception
    reraise(exc_type, exc_value, tb)
  File "/home/lya/doc/new_flasky/venv/lib/python3.6/site-packages/flask/_compat.py", line 35, in reraise
    raise value
  File "/home/lya/doc/new_flasky/venv/lib/python3.6/site-packages/flask/app.py", line 1813, in full_dispatch_request
    rv = self.dispatch_request()
  File "/home/lya/doc/new_flasky/venv/lib/python3.6/site-packages/flask/app.py", line 1799, in dispatch_request
    return self.view_functions[rule.endpoint](**req.view_args)
  File "/home/lya/doc/new_flasky/app/main/views.py", line 53, in index
    show_followed=show_followed, pagination=pagination)
  File "/home/lya/doc/new_flasky/venv/lib/python3.6/site-packages/flask/templating.py", line 133, in render_template
    ctx.app.update_template_context(context)
  File "/home/lya/doc/new_flasky/venv/lib/python3.6/site-packages/flask/app.py", line 792, in update_template_context
    context.update(func())
  File "/home/lya/doc/new_flasky/app/main/__init__.py", line 20, in inject_permissions
    greater_users=int(generate_greater_users()))
  File "/home/lya/doc/new_flasky/app/main/__init__.py", line 12, in generate_greater_users
    if int(curr) - 1 > int(greater):
TypeError: int() argument must be a string, a bytes-like object or a number, not 'NoneType'
[2018-09-19 13:02:31,791] ERROR in app: Exception on /favicon.ico [GET]
Traceback (most recent call last):
  File "/home/lya/doc/new_flasky/venv/lib/python3.6/site-packages/flask/app.py", line 1813, in full_dispatch_request
    rv = self.dispatch_request()
  File "/home/lya/doc/new_flasky/venv/lib/python3.6/site-packages/flask/app.py", line 1791, in dispatch_request
    self.raise_routing_exception(req)
  File "/home/lya/doc/new_flasky/venv/lib/python3.6/site-packages/flask/app.py", line 1774, in raise_routing_exception
    raise request.routing_exception
  File "/home/lya/doc/new_flasky/venv/lib/python3.6/site-packages/flask/ctx.py", line 336, in match_request
    self.url_adapter.match(return_rule=True)
  File "/home/lya/doc/new_flasky/venv/lib/python3.6/site-packages/werkzeug/routing.py", line 1581, in match
    raise NotFound()
werkzeug.exceptions.NotFound: 404 Not Found: The requested URL was not found on the server.  If you entered the URL manually please check your spelling and try again.

During handling of the above exception, another exception occurred:

Traceback (most recent call last):
  File "/home/lya/doc/new_flasky/venv/lib/python3.6/site-packages/flask/app.py", line 2292, in wsgi_app
    response = self.full_dispatch_request()
  File "/home/lya/doc/new_flasky/venv/lib/python3.6/site-packages/flask/app.py", line 1815, in full_dispatch_request
    rv = self.handle_user_exception(e)
  File "/home/lya/doc/new_flasky/venv/lib/python3.6/site-packages/flask/app.py", line 1713, in handle_user_exception
    return self.handle_http_exception(e)
  File "/home/lya/doc/new_flasky/venv/lib/python3.6/site-packages/flask/app.py", line 1644, in handle_http_exception
    return handler(e)
  File "/home/lya/doc/new_flasky/app/main/errors.py", line 16, in page_not_found
    return render_template('404.html'), 404
  File "/home/lya/doc/new_flasky/venv/lib/python3.6/site-packages/flask/templating.py", line 133, in render_template
    ctx.app.update_template_context(context)
  File "/home/lya/doc/new_flasky/venv/lib/python3.6/site-packages/flask/app.py", line 792, in update_template_context
    context.update(func())
  File "/home/lya/doc/new_flasky/app/main/__init__.py", line 20, in inject_permissions
    greater_users=int(generate_greater_users()))
  File "/home/lya/doc/new_flasky/app/main/__init__.py", line 12, in generate_greater_users
    if int(curr) - 1 > int(greater):
TypeError: int() argument must be a string, a bytes-like object or a number, not 'NoneType'
[2018-09-19 13:06:18,050] ERROR in app: Exception on / [GET]
Traceback (most recent call last):
  File "/home/lya/doc/new_flasky/venv/lib/python3.6/site-packages/flask/app.py", line 2292, in wsgi_app
    response = self.full_dispatch_request()
  File "/home/lya/doc/new_flasky/venv/lib/python3.6/site-packages/flask/app.py", line 1815, in full_dispatch_request
    rv = self.handle_user_exception(e)
  File "/home/lya/doc/new_flasky/venv/lib/python3.6/site-packages/flask/app.py", line 1718, in handle_user_exception
    reraise(exc_type, exc_value, tb)
  File "/home/lya/doc/new_flasky/venv/lib/python3.6/site-packages/flask/_compat.py", line 35, in reraise
    raise value
  File "/home/lya/doc/new_flasky/venv/lib/python3.6/site-packages/flask/app.py", line 1813, in full_dispatch_request
    rv = self.dispatch_request()
  File "/home/lya/doc/new_flasky/venv/lib/python3.6/site-packages/flask/app.py", line 1799, in dispatch_request
    return self.view_functions[rule.endpoint](**req.view_args)
  File "/home/lya/doc/new_flasky/app/main/views.py", line 53, in index
    show_followed=show_followed, pagination=pagination)
  File "/home/lya/doc/new_flasky/venv/lib/python3.6/site-packages/flask/templating.py", line 135, in render_template
    context, ctx.app)
  File "/home/lya/doc/new_flasky/venv/lib/python3.6/site-packages/flask/templating.py", line 117, in _render
    rv = template.render(context)
  File "/home/lya/doc/new_flasky/venv/lib/python3.6/site-packages/jinja2/asyncsupport.py", line 76, in render
    return original_render(self, *args, **kwargs)
  File "/home/lya/doc/new_flasky/venv/lib/python3.6/site-packages/jinja2/environment.py", line 1008, in render
    return self.environment.handle_exception(exc_info, True)
  File "/home/lya/doc/new_flasky/venv/lib/python3.6/site-packages/jinja2/environment.py", line 780, in handle_exception
    reraise(exc_type, exc_value, tb)
  File "/home/lya/doc/new_flasky/venv/lib/python3.6/site-packages/jinja2/_compat.py", line 37, in reraise
    raise value.with_traceback(tb)
  File "/home/lya/doc/new_flasky/app/templates/index_test.html", line 3, in top-level template code
    {% import '_macros.html' as macros %}
  File "/home/lya/doc/new_flasky/app/templates/base.html", line 1, in top-level template code
    {% extends "bootstrap/base.html" %}
  File "/home/lya/doc/new_flasky/venv/lib/python3.6/site-packages/flask_bootstrap/templates/bootstrap/base.html", line 1, in top-level template code
    {% block doc -%}
  File "/home/lya/doc/new_flasky/venv/lib/python3.6/site-packages/flask_bootstrap/templates/bootstrap/base.html", line 4, in block "doc"
    {%- block html %}
  File "/home/lya/doc/new_flasky/venv/lib/python3.6/site-packages/flask_bootstrap/templates/bootstrap/base.html", line 20, in block "html"
    {% block body -%}
  File "/home/lya/doc/new_flasky/venv/lib/python3.6/site-packages/flask_bootstrap/templates/bootstrap/base.html", line 23, in block "body"
    {% block content -%}
  File "/home/lya/doc/new_flasky/app/templates/base.html", line 75, in block "content"
    {% block page_content %}{% endblock %}
  File "/home/lya/doc/new_flasky/app/templates/index_test.html", line 45, in block "page_content"
    <p>当前在线 {{ curr_users() }} 历史最高{{ greater_users }} </p>
TypeError: 'int' object is not callable
[2018-09-19 13:07:59,838] ERROR in app: Exception on / [GET]
Traceback (most recent call last):
  File "/home/lya/doc/new_flasky/venv/lib/python3.6/site-packages/flask/app.py", line 2292, in wsgi_app
    response = self.full_dispatch_request()
  File "/home/lya/doc/new_flasky/venv/lib/python3.6/site-packages/flask/app.py", line 1815, in full_dispatch_request
    rv = self.handle_user_exception(e)
  File "/home/lya/doc/new_flasky/venv/lib/python3.6/site-packages/flask/app.py", line 1718, in handle_user_exception
    reraise(exc_type, exc_value, tb)
  File "/home/lya/doc/new_flasky/venv/lib/python3.6/site-packages/flask/_compat.py", line 35, in reraise
    raise value
  File "/home/lya/doc/new_flasky/venv/lib/python3.6/site-packages/flask/app.py", line 1813, in full_dispatch_request
    rv = self.dispatch_request()
  File "/home/lya/doc/new_flasky/venv/lib/python3.6/site-packages/flask/app.py", line 1799, in dispatch_request
    return self.view_functions[rule.endpoint](**req.view_args)
  File "/home/lya/doc/new_flasky/app/main/views.py", line 53, in index
    show_followed=show_followed, pagination=pagination)
  File "/home/lya/doc/new_flasky/venv/lib/python3.6/site-packages/flask/templating.py", line 135, in render_template
    context, ctx.app)
  File "/home/lya/doc/new_flasky/venv/lib/python3.6/site-packages/flask/templating.py", line 117, in _render
    rv = template.render(context)
  File "/home/lya/doc/new_flasky/venv/lib/python3.6/site-packages/jinja2/asyncsupport.py", line 76, in render
    return original_render(self, *args, **kwargs)
  File "/home/lya/doc/new_flasky/venv/lib/python3.6/site-packages/jinja2/environment.py", line 1008, in render
    return self.environment.handle_exception(exc_info, True)
  File "/home/lya/doc/new_flasky/venv/lib/python3.6/site-packages/jinja2/environment.py", line 780, in handle_exception
    reraise(exc_type, exc_value, tb)
  File "/home/lya/doc/new_flasky/venv/lib/python3.6/site-packages/jinja2/_compat.py", line 37, in reraise
    raise value.with_traceback(tb)
  File "/home/lya/doc/new_flasky/app/templates/index_test.html", line 3, in top-level template code
    {% import '_macros.html' as macros %}
  File "/home/lya/doc/new_flasky/app/templates/base.html", line 1, in top-level template code
    {% extends "bootstrap/base.html" %}
  File "/home/lya/doc/new_flasky/venv/lib/python3.6/site-packages/flask_bootstrap/templates/bootstrap/base.html", line 1, in top-level template code
    {% block doc -%}
  File "/home/lya/doc/new_flasky/venv/lib/python3.6/site-packages/flask_bootstrap/templates/bootstrap/base.html", line 4, in block "doc"
    {%- block html %}
  File "/home/lya/doc/new_flasky/venv/lib/python3.6/site-packages/flask_bootstrap/templates/bootstrap/base.html", line 20, in block "html"
    {% block body -%}
  File "/home/lya/doc/new_flasky/venv/lib/python3.6/site-packages/flask_bootstrap/templates/bootstrap/base.html", line 23, in block "body"
    {% block content -%}
  File "/home/lya/doc/new_flasky/app/templates/base.html", line 75, in block "content"
    {% block page_content %}{% endblock %}
  File "/home/lya/doc/new_flasky/app/templates/index_test.html", line 45, in block "page_content"
    <p>当前在线 {{ curr_users() }} 历史最高{{ greater_users }} </p>
TypeError: 'int' object is not callable
[2018-09-19 13:09:08,446] ERROR in app: Exception on / [GET]
Traceback (most recent call last):
  File "/home/lya/doc/new_flasky/venv/lib/python3.6/site-packages/flask/app.py", line 2292, in wsgi_app
    response = self.full_dispatch_request()
  File "/home/lya/doc/new_flasky/venv/lib/python3.6/site-packages/flask/app.py", line 1815, in full_dispatch_request
    rv = self.handle_user_exception(e)
  File "/home/lya/doc/new_flasky/venv/lib/python3.6/site-packages/flask/app.py", line 1718, in handle_user_exception
    reraise(exc_type, exc_value, tb)
  File "/home/lya/doc/new_flasky/venv/lib/python3.6/site-packages/flask/_compat.py", line 35, in reraise
    raise value
  File "/home/lya/doc/new_flasky/venv/lib/python3.6/site-packages/flask/app.py", line 1813, in full_dispatch_request
    rv = self.dispatch_request()
  File "/home/lya/doc/new_flasky/venv/lib/python3.6/site-packages/flask/app.py", line 1799, in dispatch_request
    return self.view_functions[rule.endpoint](**req.view_args)
  File "/home/lya/doc/new_flasky/app/main/views.py", line 53, in index
    show_followed=show_followed, pagination=pagination)
  File "/home/lya/doc/new_flasky/venv/lib/python3.6/site-packages/flask/templating.py", line 135, in render_template
    context, ctx.app)
  File "/home/lya/doc/new_flasky/venv/lib/python3.6/site-packages/flask/templating.py", line 117, in _render
    rv = template.render(context)
  File "/home/lya/doc/new_flasky/venv/lib/python3.6/site-packages/jinja2/asyncsupport.py", line 76, in render
    return original_render(self, *args, **kwargs)
  File "/home/lya/doc/new_flasky/venv/lib/python3.6/site-packages/jinja2/environment.py", line 1008, in render
    return self.environment.handle_exception(exc_info, True)
  File "/home/lya/doc/new_flasky/venv/lib/python3.6/site-packages/jinja2/environment.py", line 780, in handle_exception
    reraise(exc_type, exc_value, tb)
  File "/home/lya/doc/new_flasky/venv/lib/python3.6/site-packages/jinja2/_compat.py", line 37, in reraise
    raise value.with_traceback(tb)
  File "/home/lya/doc/new_flasky/app/templates/index_test.html", line 3, in top-level template code
    {% import '_macros.html' as macros %}
  File "/home/lya/doc/new_flasky/app/templates/base.html", line 1, in top-level template code
    {% extends "bootstrap/base.html" %}
  File "/home/lya/doc/new_flasky/venv/lib/python3.6/site-packages/flask_bootstrap/templates/bootstrap/base.html", line 1, in top-level template code
    {% block doc -%}
  File "/home/lya/doc/new_flasky/venv/lib/python3.6/site-packages/flask_bootstrap/templates/bootstrap/base.html", line 4, in block "doc"
    {%- block html %}
  File "/home/lya/doc/new_flasky/venv/lib/python3.6/site-packages/flask_bootstrap/templates/bootstrap/base.html", line 20, in block "html"
    {% block body -%}
  File "/home/lya/doc/new_flasky/venv/lib/python3.6/site-packages/flask_bootstrap/templates/bootstrap/base.html", line 23, in block "body"
    {% block content -%}
  File "/home/lya/doc/new_flasky/app/templates/base.html", line 75, in block "content"
    {% block page_content %}{% endblock %}
  File "/home/lya/doc/new_flasky/app/templates/index_test.html", line 45, in block "page_content"
    <p>当前在线 {{ curr_users() }} 历史最高{{ greater_users }} </p>
TypeError: 'int' object is not callable
[2018-09-19 13:15:50,723] ERROR in app: 
Traceback (most recent call last):
  File "/home/lya/doc/new_flasky/venv/lib/python3.6/site-packages/flask/app.py", line 2292, in wsgi_app
    response = self.full_dispatch_request()
  File "/home/lya/doc/new_flasky/venv/lib/python3.6/site-packages/flask/app.py", line 1815, in full_dispatch_request
    rv = self.handle_user_exception(e)
  File "/home/lya/doc/new_flasky/venv/lib/python3.6/site-packages/flask/app.py", line 1718, in handle_user_exception
    reraise(exc_type, exc_value, tb)
  File "/home/lya/doc/new_flasky/venv/lib/python3.6/site-packages/flask/_compat.py", line 35, in reraise
    raise value
  File "/home/lya/doc/new_flasky/venv/lib/python3.6/site-packages/flask/app.py", line 1813, in full_dispatch_request
    rv = self.dispatch_request()
  File "/home/lya/doc/new_flasky/venv/lib/python3.6/site-packages/flask/app.py", line 1799, in dispatch_request
    return self.view_functions[rule.endpoint](**req.view_args)
  File "/home/lya/doc/new_flasky/app/main/views.py", line 53, in index
    show_followed=show_followed, pagination=pagination)
  File "/home/lya/doc/new_flasky/venv/lib/python3.6/site-packages/flask/templating.py", line 135, in render_template
    context, ctx.app)
  File "/home/lya/doc/new_flasky/venv/lib/python3.6/site-packages/flask/templating.py", line 117, in _render
    rv = template.render(context)
  File "/home/lya/doc/new_flasky/venv/lib/python3.6/site-packages/jinja2/asyncsupport.py", line 76, in render
    return original_render(self, *args, **kwargs)
  File "/home/lya/doc/new_flasky/venv/lib/python3.6/site-packages/jinja2/environment.py", line 1008, in render
    return self.environment.handle_exception(exc_info, True)
  File "/home/lya/doc/new_flasky/venv/lib/python3.6/site-packages/jinja2/environment.py", line 780, in handle_exception
    reraise(exc_type, exc_value, tb)
  File "/home/lya/doc/new_flasky/venv/lib/python3.6/site-packages/jinja2/_compat.py", line 37, in reraise
    raise value.with_traceback(tb)
  File "/home/lya/doc/new_flasky/app/templates/index_test.html", line 3, in top-level template code
    {% import '_macros.html' as macros %}
  File "/home/lya/doc/new_flasky/app/templates/base.html", line 1, in top-level template code
    {% extends "bootstrap/base.html" %}
  File "/home/lya/doc/new_flasky/venv/lib/python3.6/site-packages/flask_bootstrap/templates/bootstrap/base.html", line 1, in top-level template code
    {% block doc -%}
  File "/home/lya/doc/new_flasky/venv/lib/python3.6/site-packages/flask_bootstrap/templates/bootstrap/base.html", line 4, in block "doc"
    {%- block html %}
  File "/home/lya/doc/new_flasky/venv/lib/python3.6/site-packages/flask_bootstrap/templates/bootstrap/base.html", line 20, in block "html"
    {% block body -%}
  File "/home/lya/doc/new_flasky/venv/lib/python3.6/site-packages/flask_bootstrap/templates/bootstrap/base.html", line 23, in block "body"
    {% block content -%}
  File "/home/lya/doc/new_flasky/app/templates/base.html", line 75, in block "content"
    {% block page_content %}{% endblock %}
  File "/home/lya/doc/new_flasky/app/templates/index_test.html", line 45, in block "page_content"
    <p>当前在线 {{ curr_users() }} 历史最高{{ greater_users }} </p>
TypeError: 'int' object is not callable
Exception on / [GET]
Traceback (most recent call last):
  File "/home/lya/doc/new_flasky/venv/lib/python3.6/site-packages/flask/app.py", line 2292, in wsgi_app
    response = self.full_dispatch_request()
  File "/home/lya/doc/new_flasky/venv/lib/python3.6/site-packages/flask/app.py", line 1815, in full_dispatch_request
    rv = self.handle_user_exception(e)
  File "/home/lya/doc/new_flasky/venv/lib/python3.6/site-packages/flask/app.py", line 1718, in handle_user_exception
    reraise(exc_type, exc_value, tb)
  File "/home/lya/doc/new_flasky/venv/lib/python3.6/site-packages/flask/_compat.py", line 35, in reraise
    raise value
  File "/home/lya/doc/new_flasky/venv/lib/python3.6/site-packages/flask/app.py", line 1813, in full_dispatch_request
    rv = self.dispatch_request()
  File "/home/lya/doc/new_flasky/venv/lib/python3.6/site-packages/flask/app.py", line 1799, in dispatch_request
    return self.view_functions[rule.endpoint](**req.view_args)
  File "/home/lya/doc/new_flasky/app/main/views.py", line 53, in index
    show_followed=show_followed, pagination=pagination)
  File "/home/lya/doc/new_flasky/venv/lib/python3.6/site-packages/flask/templating.py", line 135, in render_template
    context, ctx.app)
  File "/home/lya/doc/new_flasky/venv/lib/python3.6/site-packages/flask/templating.py", line 117, in _render
    rv = template.render(context)
  File "/home/lya/doc/new_flasky/venv/lib/python3.6/site-packages/jinja2/asyncsupport.py", line 76, in render
    return original_render(self, *args, **kwargs)
  File "/home/lya/doc/new_flasky/venv/lib/python3.6/site-packages/jinja2/environment.py", line 1008, in render
    return self.environment.handle_exception(exc_info, True)
  File "/home/lya/doc/new_flasky/venv/lib/python3.6/site-packages/jinja2/environment.py", line 780, in handle_exception
    reraise(exc_type, exc_value, tb)
  File "/home/lya/doc/new_flasky/venv/lib/python3.6/site-packages/jinja2/_compat.py", line 37, in reraise
    raise value.with_traceback(tb)
  File "/home/lya/doc/new_flasky/app/templates/index_test.html", line 3, in top-level template code
    {% import '_macros.html' as macros %}
  File "/home/lya/doc/new_flasky/app/templates/base.html", line 1, in top-level template code
    {% extends "bootstrap/base.html" %}
  File "/home/lya/doc/new_flasky/venv/lib/python3.6/site-packages/flask_bootstrap/templates/bootstrap/base.html", line 1, in top-level template code
    {% block doc -%}
  File "/home/lya/doc/new_flasky/venv/lib/python3.6/site-packages/flask_bootstrap/templates/bootstrap/base.html", line 4, in block "doc"
    {%- block html %}
  File "/home/lya/doc/new_flasky/venv/lib/python3.6/site-packages/flask_bootstrap/templates/bootstrap/base.html", line 20, in block "html"
    {% block body -%}
  File "/home/lya/doc/new_flasky/venv/lib/python3.6/site-packages/flask_bootstrap/templates/bootstrap/base.html", line 23, in block "body"
    {% block content -%}
  File "/home/lya/doc/new_flasky/app/templates/base.html", line 75, in block "content"
    {% block page_content %}{% endblock %}
  File "/home/lya/doc/new_flasky/app/templates/index_test.html", line 45, in block "page_content"
    <p>当前在线 {{ curr_users() }} 历史最高{{ greater_users }} </p>
TypeError: 'int' object is not callable
Exception on / [GET]
Traceback (most recent call last):
  File "/home/lya/doc/new_flasky/venv/lib/python3.6/site-packages/flask/app.py", line 2292, in wsgi_app
    response = self.full_dispatch_request()
  File "/home/lya/doc/new_flasky/venv/lib/python3.6/site-packages/flask/app.py", line 1815, in full_dispatch_request
    rv = self.handle_user_exception(e)
  File "/home/lya/doc/new_flasky/venv/lib/python3.6/site-packages/flask/app.py", line 1718, in handle_user_exception
    reraise(exc_type, exc_value, tb)
  File "/home/lya/doc/new_flasky/venv/lib/python3.6/site-packages/flask/_compat.py", line 35, in reraise
    raise value
  File "/home/lya/doc/new_flasky/venv/lib/python3.6/site-packages/flask/app.py", line 1813, in full_dispatch_request
    rv = self.dispatch_request()
  File "/home/lya/doc/new_flasky/venv/lib/python3.6/site-packages/flask/app.py", line 1799, in dispatch_request
    return self.view_functions[rule.endpoint](**req.view_args)
  File "/home/lya/doc/new_flasky/app/main/views.py", line 53, in index
    show_followed=show_followed, pagination=pagination)
  File "/home/lya/doc/new_flasky/venv/lib/python3.6/site-packages/flask/templating.py", line 135, in render_template
    context, ctx.app)
  File "/home/lya/doc/new_flasky/venv/lib/python3.6/site-packages/flask/templating.py", line 117, in _render
    rv = template.render(context)
  File "/home/lya/doc/new_flasky/venv/lib/python3.6/site-packages/jinja2/asyncsupport.py", line 76, in render
    return original_render(self, *args, **kwargs)
  File "/home/lya/doc/new_flasky/venv/lib/python3.6/site-packages/jinja2/environment.py", line 1008, in render
    return self.environment.handle_exception(exc_info, True)
  File "/home/lya/doc/new_flasky/venv/lib/python3.6/site-packages/jinja2/environment.py", line 780, in handle_exception
    reraise(exc_type, exc_value, tb)
  File "/home/lya/doc/new_flasky/venv/lib/python3.6/site-packages/jinja2/_compat.py", line 37, in reraise
    raise value.with_traceback(tb)
  File "/home/lya/doc/new_flasky/app/templates/index_test.html", line 3, in top-level template code
    {% import '_macros.html' as macros %}
  File "/home/lya/doc/new_flasky/app/templates/base.html", line 1, in top-level template code
    {% extends "bootstrap/base.html" %}
  File "/home/lya/doc/new_flasky/venv/lib/python3.6/site-packages/flask_bootstrap/templates/bootstrap/base.html", line 1, in top-level template code
    {% block doc -%}
  File "/home/lya/doc/new_flasky/venv/lib/python3.6/site-packages/flask_bootstrap/templates/bootstrap/base.html", line 4, in block "doc"
    {%- block html %}
  File "/home/lya/doc/new_flasky/venv/lib/python3.6/site-packages/flask_bootstrap/templates/bootstrap/base.html", line 20, in block "html"
    {% block body -%}
  File "/home/lya/doc/new_flasky/venv/lib/python3.6/site-packages/flask_bootstrap/templates/bootstrap/base.html", line 23, in block "body"
    {% block content -%}
  File "/home/lya/doc/new_flasky/app/templates/base.html", line 75, in block "content"
    {% block page_content %}{% endblock %}
  File "/home/lya/doc/new_flasky/app/templates/index_test.html", line 45, in block "page_content"
    <p>当前在线 {{ curr_users() }} 历史最高{{ greater_users }} </p>
TypeError: 'int' object is not callable
[2018-09-19 13:20:52,826] ERROR in app :Exception on / [GET]
Traceback (most recent call last):
  File "/home/lya/doc/new_flasky/venv/lib/python3.6/site-packages/flask/app.py", line 2292, in wsgi_app
    response = self.full_dispatch_request()
  File "/home/lya/doc/new_flasky/venv/lib/python3.6/site-packages/flask/app.py", line 1815, in full_dispatch_request
    rv = self.handle_user_exception(e)
  File "/home/lya/doc/new_flasky/venv/lib/python3.6/site-packages/flask/app.py", line 1718, in handle_user_exception
    reraise(exc_type, exc_value, tb)
  File "/home/lya/doc/new_flasky/venv/lib/python3.6/site-packages/flask/_compat.py", line 35, in reraise
    raise value
  File "/home/lya/doc/new_flasky/venv/lib/python3.6/site-packages/flask/app.py", line 1813, in full_dispatch_request
    rv = self.dispatch_request()
  File "/home/lya/doc/new_flasky/venv/lib/python3.6/site-packages/flask/app.py", line 1799, in dispatch_request
    return self.view_functions[rule.endpoint](**req.view_args)
  File "/home/lya/doc/new_flasky/app/main/views.py", line 53, in index
    show_followed=show_followed, pagination=pagination)
  File "/home/lya/doc/new_flasky/venv/lib/python3.6/site-packages/flask/templating.py", line 135, in render_template
    context, ctx.app)
  File "/home/lya/doc/new_flasky/venv/lib/python3.6/site-packages/flask/templating.py", line 117, in _render
    rv = template.render(context)
  File "/home/lya/doc/new_flasky/venv/lib/python3.6/site-packages/jinja2/asyncsupport.py", line 76, in render
    return original_render(self, *args, **kwargs)
  File "/home/lya/doc/new_flasky/venv/lib/python3.6/site-packages/jinja2/environment.py", line 1008, in render
    return self.environment.handle_exception(exc_info, True)
  File "/home/lya/doc/new_flasky/venv/lib/python3.6/site-packages/jinja2/environment.py", line 780, in handle_exception
    reraise(exc_type, exc_value, tb)
  File "/home/lya/doc/new_flasky/venv/lib/python3.6/site-packages/jinja2/_compat.py", line 37, in reraise
    raise value.with_traceback(tb)
  File "/home/lya/doc/new_flasky/app/templates/index_test.html", line 3, in top-level template code
    {% import '_macros.html' as macros %}
  File "/home/lya/doc/new_flasky/app/templates/base.html", line 1, in top-level template code
    {% extends "bootstrap/base.html" %}
  File "/home/lya/doc/new_flasky/venv/lib/python3.6/site-packages/flask_bootstrap/templates/bootstrap/base.html", line 1, in top-level template code
    {% block doc -%}
  File "/home/lya/doc/new_flasky/venv/lib/python3.6/site-packages/flask_bootstrap/templates/bootstrap/base.html", line 4, in block "doc"
    {%- block html %}
  File "/home/lya/doc/new_flasky/venv/lib/python3.6/site-packages/flask_bootstrap/templates/bootstrap/base.html", line 20, in block "html"
    {% block body -%}
  File "/home/lya/doc/new_flasky/venv/lib/python3.6/site-packages/flask_bootstrap/templates/bootstrap/base.html", line 23, in block "body"
    {% block content -%}
  File "/home/lya/doc/new_flasky/app/templates/base.html", line 75, in block "content"
    {% block page_content %}{% endblock %}
  File "/home/lya/doc/new_flasky/app/templates/index_test.html", line 45, in block "page_content"
    <p>当前在线 {{ curr_users() }} 历史最高{{ greater_users }} </p>
TypeError: 'int' object is not callable
[2018-09-19 13:26:11,284] ERROR in app: Exception on / [GET]
Traceback (most recent call last):
  File "/home/lya/doc/new_flasky/venv/lib/python3.6/site-packages/flask/app.py", line 2292, in wsgi_app
    response = self.full_dispatch_request()
  File "/home/lya/doc/new_flasky/venv/lib/python3.6/site-packages/flask/app.py", line 1815, in full_dispatch_request
    rv = self.handle_user_exception(e)
  File "/home/lya/doc/new_flasky/venv/lib/python3.6/site-packages/flask/app.py", line 1718, in handle_user_exception
    reraise(exc_type, exc_value, tb)
  File "/home/lya/doc/new_flasky/venv/lib/python3.6/site-packages/flask/_compat.py", line 35, in reraise
    raise value
  File "/home/lya/doc/new_flasky/venv/lib/python3.6/site-packages/flask/app.py", line 1813, in full_dispatch_request
    rv = self.dispatch_request()
  File "/home/lya/doc/new_flasky/venv/lib/python3.6/site-packages/flask/app.py", line 1799, in dispatch_request
    return self.view_functions[rule.endpoint](**req.view_args)
  File "/home/lya/doc/new_flasky/app/main/views.py", line 53, in index
    show_followed=show_followed, pagination=pagination)
  File "/home/lya/doc/new_flasky/venv/lib/python3.6/site-packages/flask/templating.py", line 135, in render_template
    context, ctx.app)
  File "/home/lya/doc/new_flasky/venv/lib/python3.6/site-packages/flask/templating.py", line 117, in _render
    rv = template.render(context)
  File "/home/lya/doc/new_flasky/venv/lib/python3.6/site-packages/jinja2/asyncsupport.py", line 76, in render
    return original_render(self, *args, **kwargs)
  File "/home/lya/doc/new_flasky/venv/lib/python3.6/site-packages/jinja2/environment.py", line 1008, in render
    return self.environment.handle_exception(exc_info, True)
  File "/home/lya/doc/new_flasky/venv/lib/python3.6/site-packages/jinja2/environment.py", line 780, in handle_exception
    reraise(exc_type, exc_value, tb)
  File "/home/lya/doc/new_flasky/venv/lib/python3.6/site-packages/jinja2/_compat.py", line 37, in reraise
    raise value.with_traceback(tb)
  File "/home/lya/doc/new_flasky/app/templates/index_test.html", line 3, in top-level template code
    {% import '_macros.html' as macros %}
  File "/home/lya/doc/new_flasky/app/templates/base.html", line 1, in top-level template code
    {% extends "bootstrap/base.html" %}
  File "/home/lya/doc/new_flasky/venv/lib/python3.6/site-packages/flask_bootstrap/templates/bootstrap/base.html", line 1, in top-level template code
    {% block doc -%}
  File "/home/lya/doc/new_flasky/venv/lib/python3.6/site-packages/flask_bootstrap/templates/bootstrap/base.html", line 4, in block "doc"
    {%- block html %}
  File "/home/lya/doc/new_flasky/venv/lib/python3.6/site-packages/flask_bootstrap/templates/bootstrap/base.html", line 20, in block "html"
    {% block body -%}
  File "/home/lya/doc/new_flasky/venv/lib/python3.6/site-packages/flask_bootstrap/templates/bootstrap/base.html", line 23, in block "body"
    {% block content -%}
  File "/home/lya/doc/new_flasky/app/templates/base.html", line 75, in block "content"
    {% block page_content %}{% endblock %}
  File "/home/lya/doc/new_flasky/app/templates/index_test.html", line 45, in block "page_content"
    <p>当前在线 {{ curr_users() }} 历史最高{{ greater_users }} </p>
TypeError: 'int' object is not callable
[2018-09-20 09:38:58,160] ERROR in app: Exception on / [GET]
Traceback (most recent call last):
  File "/home/lya/doc/new_flasky/venv/lib/python3.6/site-packages/flask/app.py", line 2292, in wsgi_app
    response = self.full_dispatch_request()
  File "/home/lya/doc/new_flasky/venv/lib/python3.6/site-packages/flask/app.py", line 1815, in full_dispatch_request
    rv = self.handle_user_exception(e)
  File "/home/lya/doc/new_flasky/venv/lib/python3.6/site-packages/flask/app.py", line 1718, in handle_user_exception
    reraise(exc_type, exc_value, tb)
  File "/home/lya/doc/new_flasky/venv/lib/python3.6/site-packages/flask/_compat.py", line 35, in reraise
    raise value
  File "/home/lya/doc/new_flasky/venv/lib/python3.6/site-packages/flask/app.py", line 1813, in full_dispatch_request
    rv = self.dispatch_request()
  File "/home/lya/doc/new_flasky/venv/lib/python3.6/site-packages/flask/app.py", line 1799, in dispatch_request
    return self.view_functions[rule.endpoint](**req.view_args)
  File "/home/lya/doc/new_flasky/app/main/views.py", line 53, in index
    show_followed=show_followed, pagination=pagination)
  File "/home/lya/doc/new_flasky/venv/lib/python3.6/site-packages/flask/templating.py", line 133, in render_template
    ctx.app.update_template_context(context)
  File "/home/lya/doc/new_flasky/venv/lib/python3.6/site-packages/flask/app.py", line 792, in update_template_context
    context.update(func())
  File "/home/lya/doc/new_flasky/app/main/__init__.py", line 20, in inject_permissions
    greater_users=int(generate_greater_users()))
  File "/home/lya/doc/new_flasky/app/main/__init__.py", line 12, in generate_greater_users
    if int(curr) - 1 > int(greater):
TypeError: int() argument must be a string, a bytes-like object or a number, not 'NoneType'
[2018-09-20 09:38:59,007] ERROR in app: Exception on /favicon.ico [GET]
Traceback (most recent call last):
  File "/home/lya/doc/new_flasky/venv/lib/python3.6/site-packages/flask/app.py", line 1813, in full_dispatch_request
    rv = self.dispatch_request()
  File "/home/lya/doc/new_flasky/venv/lib/python3.6/site-packages/flask/app.py", line 1791, in dispatch_request
    self.raise_routing_exception(req)
  File "/home/lya/doc/new_flasky/venv/lib/python3.6/site-packages/flask/app.py", line 1774, in raise_routing_exception
    raise request.routing_exception
  File "/home/lya/doc/new_flasky/venv/lib/python3.6/site-packages/flask/ctx.py", line 336, in match_request
    self.url_adapter.match(return_rule=True)
  File "/home/lya/doc/new_flasky/venv/lib/python3.6/site-packages/werkzeug/routing.py", line 1581, in match
    raise NotFound()
werkzeug.exceptions.NotFound: 404 Not Found: The requested URL was not found on the server.  If you entered the URL manually please check your spelling and try again.

During handling of the above exception, another exception occurred:

Traceback (most recent call last):
  File "/home/lya/doc/new_flasky/venv/lib/python3.6/site-packages/flask/app.py", line 2292, in wsgi_app
    response = self.full_dispatch_request()
  File "/home/lya/doc/new_flasky/venv/lib/python3.6/site-packages/flask/app.py", line 1815, in full_dispatch_request
    rv = self.handle_user_exception(e)
  File "/home/lya/doc/new_flasky/venv/lib/python3.6/site-packages/flask/app.py", line 1713, in handle_user_exception
    return self.handle_http_exception(e)
  File "/home/lya/doc/new_flasky/venv/lib/python3.6/site-packages/flask/app.py", line 1644, in handle_http_exception
    return handler(e)
  File "/home/lya/doc/new_flasky/app/main/errors.py", line 16, in page_not_found
    return render_template('404.html'), 404
  File "/home/lya/doc/new_flasky/venv/lib/python3.6/site-packages/flask/templating.py", line 133, in render_template
    ctx.app.update_template_context(context)
  File "/home/lya/doc/new_flasky/venv/lib/python3.6/site-packages/flask/app.py", line 792, in update_template_context
    context.update(func())
  File "/home/lya/doc/new_flasky/app/main/__init__.py", line 20, in inject_permissions
    greater_users=int(generate_greater_users()))
  File "/home/lya/doc/new_flasky/app/main/__init__.py", line 12, in generate_greater_users
    if int(curr) - 1 > int(greater):
TypeError: int() argument must be a string, a bytes-like object or a number, not 'NoneType'
[2018-09-29 11:25:34,364] ERROR in app: Exception on / [GET]
Traceback (most recent call last):
  File "/home/lya/doc/new_flasky/venv/lib/python3.6/site-packages/flask/app.py", line 2292, in wsgi_app
    response = self.full_dispatch_request()
  File "/home/lya/doc/new_flasky/venv/lib/python3.6/site-packages/flask/app.py", line 1815, in full_dispatch_request
    rv = self.handle_user_exception(e)
  File "/home/lya/doc/new_flasky/venv/lib/python3.6/site-packages/flask/app.py", line 1718, in handle_user_exception
    reraise(exc_type, exc_value, tb)
  File "/home/lya/doc/new_flasky/venv/lib/python3.6/site-packages/flask/_compat.py", line 35, in reraise
    raise value
  File "/home/lya/doc/new_flasky/venv/lib/python3.6/site-packages/flask/app.py", line 1813, in full_dispatch_request
    rv = self.dispatch_request()
  File "/home/lya/doc/new_flasky/venv/lib/python3.6/site-packages/flask/app.py", line 1799, in dispatch_request
    return self.view_functions[rule.endpoint](**req.view_args)
  File "/home/lya/doc/new_flasky/app/main/views.py", line 53, in index
    show_followed=show_followed, pagination=pagination)
  File "/home/lya/doc/new_flasky/venv/lib/python3.6/site-packages/flask/templating.py", line 133, in render_template
    ctx.app.update_template_context(context)
  File "/home/lya/doc/new_flasky/venv/lib/python3.6/site-packages/flask/app.py", line 792, in update_template_context
    context.update(func())
  File "/home/lya/doc/new_flasky/app/main/__init__.py", line 20, in inject_permissions
    greater_users=int(generate_greater_users()))
  File "/home/lya/doc/new_flasky/app/main/__init__.py", line 12, in generate_greater_users
    if int(curr) - 1 > int(greater):
TypeError: int() argument must be a string, a bytes-like object or a number, not 'NoneType'
[2018-09-29 11:25:35,201] ERROR in app: Exception on /favicon.ico [GET]
Traceback (most recent call last):
  File "/home/lya/doc/new_flasky/venv/lib/python3.6/site-packages/flask/app.py", line 1813, in full_dispatch_request
    rv = self.dispatch_request()
  File "/home/lya/doc/new_flasky/venv/lib/python3.6/site-packages/flask/app.py", line 1791, in dispatch_request
    self.raise_routing_exception(req)
  File "/home/lya/doc/new_flasky/venv/lib/python3.6/site-packages/flask/app.py", line 1774, in raise_routing_exception
    raise request.routing_exception
  File "/home/lya/doc/new_flasky/venv/lib/python3.6/site-packages/flask/ctx.py", line 336, in match_request
    self.url_adapter.match(return_rule=True)
  File "/home/lya/doc/new_flasky/venv/lib/python3.6/site-packages/werkzeug/routing.py", line 1581, in match
    raise NotFound()
werkzeug.exceptions.NotFound: 404 Not Found: The requested URL was not found on the server.  If you entered the URL manually please check your spelling and try again.

During handling of the above exception, another exception occurred:

Traceback (most recent call last):
  File "/home/lya/doc/new_flasky/venv/lib/python3.6/site-packages/flask/app.py", line 2292, in wsgi_app
    response = self.full_dispatch_request()
  File "/home/lya/doc/new_flasky/venv/lib/python3.6/site-packages/flask/app.py", line 1815, in full_dispatch_request
    rv = self.handle_user_exception(e)
  File "/home/lya/doc/new_flasky/venv/lib/python3.6/site-packages/flask/app.py", line 1713, in handle_user_exception
    return self.handle_http_exception(e)
  File "/home/lya/doc/new_flasky/venv/lib/python3.6/site-packages/flask/app.py", line 1644, in handle_http_exception
    return handler(e)
  File "/home/lya/doc/new_flasky/app/main/errors.py", line 16, in page_not_found
    return render_template('404.html'), 404
  File "/home/lya/doc/new_flasky/venv/lib/python3.6/site-packages/flask/templating.py", line 133, in render_template
    ctx.app.update_template_context(context)
  File "/home/lya/doc/new_flasky/venv/lib/python3.6/site-packages/flask/app.py", line 792, in update_template_context
    context.update(func())
  File "/home/lya/doc/new_flasky/app/main/__init__.py", line 20, in inject_permissions
    greater_users=int(generate_greater_users()))
  File "/home/lya/doc/new_flasky/app/main/__init__.py", line 12, in generate_greater_users
    if int(curr) - 1 > int(greater):
TypeError: int() argument must be a string, a bytes-like object or a number, not 'NoneType'
[2018-09-29 11:25:38,294] ERROR in app: Exception on / [GET]
Traceback (most recent call last):
  File "/home/lya/doc/new_flasky/venv/lib/python3.6/site-packages/flask/app.py", line 2292, in wsgi_app
    response = self.full_dispatch_request()
  File "/home/lya/doc/new_flasky/venv/lib/python3.6/site-packages/flask/app.py", line 1815, in full_dispatch_request
    rv = self.handle_user_exception(e)
  File "/home/lya/doc/new_flasky/venv/lib/python3.6/site-packages/flask/app.py", line 1718, in handle_user_exception
    reraise(exc_type, exc_value, tb)
  File "/home/lya/doc/new_flasky/venv/lib/python3.6/site-packages/flask/_compat.py", line 35, in reraise
    raise value
  File "/home/lya/doc/new_flasky/venv/lib/python3.6/site-packages/flask/app.py", line 1813, in full_dispatch_request
    rv = self.dispatch_request()
  File "/home/lya/doc/new_flasky/venv/lib/python3.6/site-packages/flask/app.py", line 1799, in dispatch_request
    return self.view_functions[rule.endpoint](**req.view_args)
  File "/home/lya/doc/new_flasky/app/main/views.py", line 53, in index
    show_followed=show_followed, pagination=pagination)
  File "/home/lya/doc/new_flasky/venv/lib/python3.6/site-packages/flask/templating.py", line 133, in render_template
    ctx.app.update_template_context(context)
  File "/home/lya/doc/new_flasky/venv/lib/python3.6/site-packages/flask/app.py", line 792, in update_template_context
    context.update(func())
  File "/home/lya/doc/new_flasky/app/main/__init__.py", line 20, in inject_permissions
    greater_users=int(generate_greater_users()))
  File "/home/lya/doc/new_flasky/app/main/__init__.py", line 12, in generate_greater_users
    if int(curr) - 1 > int(greater):
TypeError: int() argument must be a string, a bytes-like object or a number, not 'NoneType'
[2018-09-29 11:25:38,849] ERROR in app: Exception on /favicon.ico [GET]
Traceback (most recent call last):
  File "/home/lya/doc/new_flasky/venv/lib/python3.6/site-packages/flask/app.py", line 1813, in full_dispatch_request
    rv = self.dispatch_request()
  File "/home/lya/doc/new_flasky/venv/lib/python3.6/site-packages/flask/app.py", line 1791, in dispatch_request
    self.raise_routing_exception(req)
  File "/home/lya/doc/new_flasky/venv/lib/python3.6/site-packages/flask/app.py", line 1774, in raise_routing_exception
    raise request.routing_exception
  File "/home/lya/doc/new_flasky/venv/lib/python3.6/site-packages/flask/ctx.py", line 336, in match_request
    self.url_adapter.match(return_rule=True)
  File "/home/lya/doc/new_flasky/venv/lib/python3.6/site-packages/werkzeug/routing.py", line 1581, in match
    raise NotFound()
werkzeug.exceptions.NotFound: 404 Not Found: The requested URL was not found on the server.  If you entered the URL manually please check your spelling and try again.

During handling of the above exception, another exception occurred:

Traceback (most recent call last):
  File "/home/lya/doc/new_flasky/venv/lib/python3.6/site-packages/flask/app.py", line 2292, in wsgi_app
    response = self.full_dispatch_request()
  File "/home/lya/doc/new_flasky/venv/lib/python3.6/site-packages/flask/app.py", line 1815, in full_dispatch_request
    rv = self.handle_user_exception(e)
  File "/home/lya/doc/new_flasky/venv/lib/python3.6/site-packages/flask/app.py", line 1713, in handle_user_exception
    return self.handle_http_exception(e)
  File "/home/lya/doc/new_flasky/venv/lib/python3.6/site-packages/flask/app.py", line 1644, in handle_http_exception
    return handler(e)
  File "/home/lya/doc/new_flasky/app/main/errors.py", line 16, in page_not_found
    return render_template('404.html'), 404
  File "/home/lya/doc/new_flasky/venv/lib/python3.6/site-packages/flask/templating.py", line 133, in render_template
    ctx.app.update_template_context(context)
  File "/home/lya/doc/new_flasky/venv/lib/python3.6/site-packages/flask/app.py", line 792, in update_template_context
    context.update(func())
  File "/home/lya/doc/new_flasky/app/main/__init__.py", line 20, in inject_permissions
    greater_users=int(generate_greater_users()))
  File "/home/lya/doc/new_flasky/app/main/__init__.py", line 12, in generate_greater_users
    if int(curr) - 1 > int(greater):
TypeError: int() argument must be a string, a bytes-like object or a number, not 'NoneType'
[2018-10-02 14:39:20,158] ERROR in app: Exception on / [GET]
Traceback (most recent call last):
  File "/home/lya/doc/new_flasky/venv/lib/python3.6/site-packages/flask/app.py", line 2292, in wsgi_app
    response = self.full_dispatch_request()
  File "/home/lya/doc/new_flasky/venv/lib/python3.6/site-packages/flask/app.py", line 1815, in full_dispatch_request
    rv = self.handle_user_exception(e)
  File "/home/lya/doc/new_flasky/venv/lib/python3.6/site-packages/flask/app.py", line 1718, in handle_user_exception
    reraise(exc_type, exc_value, tb)
  File "/home/lya/doc/new_flasky/venv/lib/python3.6/site-packages/flask/_compat.py", line 35, in reraise
    raise value
  File "/home/lya/doc/new_flasky/venv/lib/python3.6/site-packages/flask/app.py", line 1813, in full_dispatch_request
    rv = self.dispatch_request()
  File "/home/lya/doc/new_flasky/venv/lib/python3.6/site-packages/flask/app.py", line 1799, in dispatch_request
    return self.view_functions[rule.endpoint](**req.view_args)
  File "/home/lya/doc/new_flasky/app/main/views.py", line 53, in index
    show_followed=show_followed, pagination=pagination)
  File "/home/lya/doc/new_flasky/venv/lib/python3.6/site-packages/flask/templating.py", line 133, in render_template
    ctx.app.update_template_context(context)
  File "/home/lya/doc/new_flasky/venv/lib/python3.6/site-packages/flask/app.py", line 792, in update_template_context
    context.update(func())
  File "/home/lya/doc/new_flasky/app/main/__init__.py", line 20, in inject_permissions
    greater_users=int(generate_greater_users()))
  File "/home/lya/doc/new_flasky/app/main/__init__.py", line 12, in generate_greater_users
    if int(curr) - 1 > int(greater):
TypeError: int() argument must be a string, a bytes-like object or a number, not 'NoneType'
[2018-10-02 14:39:20,694] ERROR in app: Exception on /favicon.ico [GET]
Traceback (most recent call last):
  File "/home/lya/doc/new_flasky/venv/lib/python3.6/site-packages/flask/app.py", line 1813, in full_dispatch_request
    rv = self.dispatch_request()
  File "/home/lya/doc/new_flasky/venv/lib/python3.6/site-packages/flask/app.py", line 1791, in dispatch_request
    self.raise_routing_exception(req)
  File "/home/lya/doc/new_flasky/venv/lib/python3.6/site-packages/flask/app.py", line 1774, in raise_routing_exception
    raise request.routing_exception
  File "/home/lya/doc/new_flasky/venv/lib/python3.6/site-packages/flask/ctx.py", line 336, in match_request
    self.url_adapter.match(return_rule=True)
  File "/home/lya/doc/new_flasky/venv/lib/python3.6/site-packages/werkzeug/routing.py", line 1581, in match
    raise NotFound()
werkzeug.exceptions.NotFound: 404 Not Found: The requested URL was not found on the server.  If you entered the URL manually please check your spelling and try again.

During handling of the above exception, another exception occurred:

Traceback (most recent call last):
  File "/home/lya/doc/new_flasky/venv/lib/python3.6/site-packages/flask/app.py", line 2292, in wsgi_app
    response = self.full_dispatch_request()
  File "/home/lya/doc/new_flasky/venv/lib/python3.6/site-packages/flask/app.py", line 1815, in full_dispatch_request
    rv = self.handle_user_exception(e)
  File "/home/lya/doc/new_flasky/venv/lib/python3.6/site-packages/flask/app.py", line 1713, in handle_user_exception
    return self.handle_http_exception(e)
  File "/home/lya/doc/new_flasky/venv/lib/python3.6/site-packages/flask/app.py", line 1644, in handle_http_exception
    return handler(e)
  File "/home/lya/doc/new_flasky/app/main/errors.py", line 16, in page_not_found
    return render_template('404.html'), 404
  File "/home/lya/doc/new_flasky/venv/lib/python3.6/site-packages/flask/templating.py", line 133, in render_template
    ctx.app.update_template_context(context)
  File "/home/lya/doc/new_flasky/venv/lib/python3.6/site-packages/flask/app.py", line 792, in update_template_context
    context.update(func())
  File "/home/lya/doc/new_flasky/app/main/__init__.py", line 20, in inject_permissions
    greater_users=int(generate_greater_users()))
  File "/home/lya/doc/new_flasky/app/main/__init__.py", line 12, in generate_greater_users
    if int(curr) - 1 > int(greater):
TypeError: int() argument must be a string, a bytes-like object or a number, not 'NoneType'
[2018-10-02 15:21:33,644] ERROR in app: Exception on / [GET]
Traceback (most recent call last):
  File "/home/lya/doc/new_flasky/venv/lib/python3.6/site-packages/flask/app.py", line 2292, in wsgi_app
    response = self.full_dispatch_request()
  File "/home/lya/doc/new_flasky/venv/lib/python3.6/site-packages/flask/app.py", line 1815, in full_dispatch_request
    rv = self.handle_user_exception(e)
  File "/home/lya/doc/new_flasky/venv/lib/python3.6/site-packages/flask/app.py", line 1718, in handle_user_exception
    reraise(exc_type, exc_value, tb)
  File "/home/lya/doc/new_flasky/venv/lib/python3.6/site-packages/flask/_compat.py", line 35, in reraise
    raise value
  File "/home/lya/doc/new_flasky/venv/lib/python3.6/site-packages/flask/app.py", line 1813, in full_dispatch_request
    rv = self.dispatch_request()
  File "/home/lya/doc/new_flasky/venv/lib/python3.6/site-packages/flask/app.py", line 1799, in dispatch_request
    return self.view_functions[rule.endpoint](**req.view_args)
  File "/home/lya/doc/new_flasky/app/main/views.py", line 53, in index
    show_followed=show_followed, pagination=pagination)
  File "/home/lya/doc/new_flasky/venv/lib/python3.6/site-packages/flask/templating.py", line 133, in render_template
    ctx.app.update_template_context(context)
  File "/home/lya/doc/new_flasky/venv/lib/python3.6/site-packages/flask/app.py", line 792, in update_template_context
    context.update(func())
  File "/home/lya/doc/new_flasky/app/main/__init__.py", line 20, in inject_permissions
    greater_users=int(generate_greater_users()))
  File "/home/lya/doc/new_flasky/app/main/__init__.py", line 12, in generate_greater_users
    if int(curr) - 1 > int(greater):
TypeError: int() argument must be a string, a bytes-like object or a number, not 'NoneType'
[2018-10-02 15:21:34,296] ERROR in app: Exception on /favicon.ico [GET]
Traceback (most recent call last):
  File "/home/lya/doc/new_flasky/venv/lib/python3.6/site-packages/flask/app.py", line 1813, in full_dispatch_request
    rv = self.dispatch_request()
  File "/home/lya/doc/new_flasky/venv/lib/python3.6/site-packages/flask/app.py", line 1791, in dispatch_request
    self.raise_routing_exception(req)
  File "/home/lya/doc/new_flasky/venv/lib/python3.6/site-packages/flask/app.py", line 1774, in raise_routing_exception
    raise request.routing_exception
  File "/home/lya/doc/new_flasky/venv/lib/python3.6/site-packages/flask/ctx.py", line 336, in match_request
    self.url_adapter.match(return_rule=True)
  File "/home/lya/doc/new_flasky/venv/lib/python3.6/site-packages/werkzeug/routing.py", line 1581, in match
    raise NotFound()
werkzeug.exceptions.NotFound: 404 Not Found: The requested URL was not found on the server.  If you entered the URL manually please check your spelling and try again.

During handling of the above exception, another exception occurred:

Traceback (most recent call last):
  File "/home/lya/doc/new_flasky/venv/lib/python3.6/site-packages/flask/app.py", line 2292, in wsgi_app
    response = self.full_dispatch_request()
  File "/home/lya/doc/new_flasky/venv/lib/python3.6/site-packages/flask/app.py", line 1815, in full_dispatch_request
    rv = self.handle_user_exception(e)
  File "/home/lya/doc/new_flasky/venv/lib/python3.6/site-packages/flask/app.py", line 1713, in handle_user_exception
    return self.handle_http_exception(e)
  File "/home/lya/doc/new_flasky/venv/lib/python3.6/site-packages/flask/app.py", line 1644, in handle_http_exception
    return handler(e)
  File "/home/lya/doc/new_flasky/app/main/errors.py", line 16, in page_not_found
    return render_template('404.html'), 404
  File "/home/lya/doc/new_flasky/venv/lib/python3.6/site-packages/flask/templating.py", line 133, in render_template
    ctx.app.update_template_context(context)
  File "/home/lya/doc/new_flasky/venv/lib/python3.6/site-packages/flask/app.py", line 792, in update_template_context
    context.update(func())
  File "/home/lya/doc/new_flasky/app/main/__init__.py", line 20, in inject_permissions
    greater_users=int(generate_greater_users()))
  File "/home/lya/doc/new_flasky/app/main/__init__.py", line 12, in generate_greater_users
    if int(curr) - 1 > int(greater):
TypeError: int() argument must be a string, a bytes-like object or a number, not 'NoneType'
[2018-10-02 15:21:37,414] ERROR in app: Exception on / [GET]
Traceback (most recent call last):
  File "/home/lya/doc/new_flasky/venv/lib/python3.6/site-packages/flask/app.py", line 2292, in wsgi_app
    response = self.full_dispatch_request()
  File "/home/lya/doc/new_flasky/venv/lib/python3.6/site-packages/flask/app.py", line 1815, in full_dispatch_request
    rv = self.handle_user_exception(e)
  File "/home/lya/doc/new_flasky/venv/lib/python3.6/site-packages/flask/app.py", line 1718, in handle_user_exception
    reraise(exc_type, exc_value, tb)
  File "/home/lya/doc/new_flasky/venv/lib/python3.6/site-packages/flask/_compat.py", line 35, in reraise
    raise value
  File "/home/lya/doc/new_flasky/venv/lib/python3.6/site-packages/flask/app.py", line 1813, in full_dispatch_request
    rv = self.dispatch_request()
  File "/home/lya/doc/new_flasky/venv/lib/python3.6/site-packages/flask/app.py", line 1799, in dispatch_request
    return self.view_functions[rule.endpoint](**req.view_args)
  File "/home/lya/doc/new_flasky/app/main/views.py", line 53, in index
    show_followed=show_followed, pagination=pagination)
  File "/home/lya/doc/new_flasky/venv/lib/python3.6/site-packages/flask/templating.py", line 133, in render_template
    ctx.app.update_template_context(context)
  File "/home/lya/doc/new_flasky/venv/lib/python3.6/site-packages/flask/app.py", line 792, in update_template_context
    context.update(func())
  File "/home/lya/doc/new_flasky/app/main/__init__.py", line 20, in inject_permissions
    greater_users=int(generate_greater_users()))
  File "/home/lya/doc/new_flasky/app/main/__init__.py", line 12, in generate_greater_users
    if int(curr) - 1 > int(greater):
TypeError: int() argument must be a string, a bytes-like object or a number, not 'NoneType'
[2018-10-02 15:21:37,933] ERROR in app: Exception on /favicon.ico [GET]
Traceback (most recent call last):
  File "/home/lya/doc/new_flasky/venv/lib/python3.6/site-packages/flask/app.py", line 1813, in full_dispatch_request
    rv = self.dispatch_request()
  File "/home/lya/doc/new_flasky/venv/lib/python3.6/site-packages/flask/app.py", line 1791, in dispatch_request
    self.raise_routing_exception(req)
  File "/home/lya/doc/new_flasky/venv/lib/python3.6/site-packages/flask/app.py", line 1774, in raise_routing_exception
    raise request.routing_exception
  File "/home/lya/doc/new_flasky/venv/lib/python3.6/site-packages/flask/ctx.py", line 336, in match_request
    self.url_adapter.match(return_rule=True)
  File "/home/lya/doc/new_flasky/venv/lib/python3.6/site-packages/werkzeug/routing.py", line 1581, in match
    raise NotFound()
werkzeug.exceptions.NotFound: 404 Not Found: The requested URL was not found on the server.  If you entered the URL manually please check your spelling and try again.

During handling of the above exception, another exception occurred:

Traceback (most recent call last):
  File "/home/lya/doc/new_flasky/venv/lib/python3.6/site-packages/flask/app.py", line 2292, in wsgi_app
    response = self.full_dispatch_request()
  File "/home/lya/doc/new_flasky/venv/lib/python3.6/site-packages/flask/app.py", line 1815, in full_dispatch_request
    rv = self.handle_user_exception(e)
  File "/home/lya/doc/new_flasky/venv/lib/python3.6/site-packages/flask/app.py", line 1713, in handle_user_exception
    return self.handle_http_exception(e)
  File "/home/lya/doc/new_flasky/venv/lib/python3.6/site-packages/flask/app.py", line 1644, in handle_http_exception
    return handler(e)
  File "/home/lya/doc/new_flasky/app/main/errors.py", line 16, in page_not_found
    return render_template('404.html'), 404
  File "/home/lya/doc/new_flasky/venv/lib/python3.6/site-packages/flask/templating.py", line 133, in render_template
    ctx.app.update_template_context(context)
  File "/home/lya/doc/new_flasky/venv/lib/python3.6/site-packages/flask/app.py", line 792, in update_template_context
    context.update(func())
  File "/home/lya/doc/new_flasky/app/main/__init__.py", line 20, in inject_permissions
    greater_users=int(generate_greater_users()))
  File "/home/lya/doc/new_flasky/app/main/__init__.py", line 12, in generate_greater_users
    if int(curr) - 1 > int(greater):
TypeError: int() argument must be a string, a bytes-like object or a number, not 'NoneType'
[2018-10-02 17:45:06,526] ERROR in app: Exception on /moderate/ [GET]
Traceback (most recent call last):
  File "/home/lya/doc/new_flasky/venv/lib/python3.6/site-packages/flask/app.py", line 2292, in wsgi_app
    response = self.full_dispatch_request()
  File "/home/lya/doc/new_flasky/venv/lib/python3.6/site-packages/flask/app.py", line 1815, in full_dispatch_request
    rv = self.handle_user_exception(e)
  File "/home/lya/doc/new_flasky/venv/lib/python3.6/site-packages/flask/app.py", line 1718, in handle_user_exception
    reraise(exc_type, exc_value, tb)
  File "/home/lya/doc/new_flasky/venv/lib/python3.6/site-packages/flask/_compat.py", line 35, in reraise
    raise value
  File "/home/lya/doc/new_flasky/venv/lib/python3.6/site-packages/flask/app.py", line 1813, in full_dispatch_request
    rv = self.dispatch_request()
  File "/home/lya/doc/new_flasky/venv/lib/python3.6/site-packages/flask/app.py", line 1799, in dispatch_request
    return self.view_functions[rule.endpoint](**req.view_args)
  File "/home/lya/doc/new_flasky/venv/lib/python3.6/site-packages/flask_login/utils.py", line 261, in decorated_view
    return func(*args, **kwargs)
  File "/home/lya/doc/new_flasky/app/decorators.py", line 13, in decorated_function
    return f(*args, **kwargs)
  File "/home/lya/doc/new_flasky/app/main/views.py", line 276, in moderate
    return render_template('moderate.html', comments=comments, pagination=pagination, page=page)
  File "/home/lya/doc/new_flasky/venv/lib/python3.6/site-packages/flask/templating.py", line 135, in render_template
    context, ctx.app)
  File "/home/lya/doc/new_flasky/venv/lib/python3.6/site-packages/flask/templating.py", line 117, in _render
    rv = template.render(context)
  File "/home/lya/doc/new_flasky/venv/lib/python3.6/site-packages/jinja2/asyncsupport.py", line 76, in render
    return original_render(self, *args, **kwargs)
  File "/home/lya/doc/new_flasky/venv/lib/python3.6/site-packages/jinja2/environment.py", line 1008, in render
    return self.environment.handle_exception(exc_info, True)
  File "/home/lya/doc/new_flasky/venv/lib/python3.6/site-packages/jinja2/environment.py", line 780, in handle_exception
    reraise(exc_type, exc_value, tb)
  File "/home/lya/doc/new_flasky/venv/lib/python3.6/site-packages/jinja2/_compat.py", line 37, in reraise
    raise value.with_traceback(tb)
  File "/home/lya/doc/new_flasky/app/templates/base.html", line 67, in template
    {% endblock %}
  File "/home/lya/doc/new_flasky/venv/lib/python3.6/site-packages/jinja2/environment.py", line 1005, in render
    return concat(self.root_render_func(self.new_context(vars)))
  File "/home/lya/doc/new_flasky/app/templates/moderate.html", line 1, in top-level template code
    {% extends 'base.html' %}
  File "/home/lya/doc/new_flasky/venv/lib/python3.6/site-packages/jinja2/environment.py", line 780, in handle_exception
    reraise(exc_type, exc_value, tb)
  File "/home/lya/doc/new_flasky/venv/lib/python3.6/site-packages/jinja2/_compat.py", line 37, in reraise
    raise value.with_traceback(tb)
  File "/home/lya/doc/new_flasky/app/templates/base.html", line 67, in template
    {% endblock %}
  File "/home/lya/doc/new_flasky/venv/lib/python3.6/site-packages/jinja2/environment.py", line 497, in _parse
    return Parser(self, source, name, encode_filename(filename)).parse()
  File "/home/lya/doc/new_flasky/venv/lib/python3.6/site-packages/jinja2/parser.py", line 901, in parse
    result = nodes.Template(self.subparse(), lineno=1)
  File "/home/lya/doc/new_flasky/venv/lib/python3.6/site-packages/jinja2/parser.py", line 883, in subparse
    rv = self.parse_statement()
  File "/home/lya/doc/new_flasky/venv/lib/python3.6/site-packages/jinja2/parser.py", line 130, in parse_statement
    return getattr(self, 'parse_' + self.stream.current.value)()
  File "/home/lya/doc/new_flasky/venv/lib/python3.6/site-packages/jinja2/parser.py", line 268, in parse_block
    node.body = self.parse_statements(('name:endblock',), drop_needle=True)
  File "/home/lya/doc/new_flasky/venv/lib/python3.6/site-packages/jinja2/parser.py", line 165, in parse_statements
    result = self.subparse(end_tokens)
  File "/home/lya/doc/new_flasky/venv/lib/python3.6/site-packages/jinja2/parser.py", line 883, in subparse
    rv = self.parse_statement()
  File "/home/lya/doc/new_flasky/venv/lib/python3.6/site-packages/jinja2/parser.py", line 130, in parse_statement
    return getattr(self, 'parse_' + self.stream.current.value)()
  File "/home/lya/doc/new_flasky/venv/lib/python3.6/site-packages/jinja2/parser.py", line 213, in parse_if
    'name:endif'))
  File "/home/lya/doc/new_flasky/venv/lib/python3.6/site-packages/jinja2/parser.py", line 165, in parse_statements
    result = self.subparse(end_tokens)
  File "/home/lya/doc/new_flasky/venv/lib/python3.6/site-packages/jinja2/parser.py", line 883, in subparse
    rv = self.parse_statement()
  File "/home/lya/doc/new_flasky/venv/lib/python3.6/site-packages/jinja2/parser.py", line 144, in parse_statement
    self.fail_unknown_tag(token.value, token.lineno)
  File "/home/lya/doc/new_flasky/venv/lib/python3.6/site-packages/jinja2/parser.py", line 97, in fail_unknown_tag
    return self._fail_ut_eof(name, self._end_token_stack, lineno)
  File "/home/lya/doc/new_flasky/venv/lib/python3.6/site-packages/jinja2/parser.py", line 90, in _fail_ut_eof
    self.fail(' '.join(message), lineno)
  File "/home/lya/doc/new_flasky/venv/lib/python3.6/site-packages/jinja2/parser.py", line 59, in fail
    raise exc(msg, lineno, self.name, self.filename)
jinja2.exceptions.TemplateSyntaxError: Encountered unknown tag 'endblock'. You probably made a nesting mistake. Jinja is expecting this tag, but currently looking for 'elif' or 'else' or 'endif'. The innermost block that needs to be closed is 'if'.
[2018-10-02 17:45:07,209] ERROR in app: Exception on /favicon.ico [GET]
Traceback (most recent call last):
  File "/home/lya/doc/new_flasky/venv/lib/python3.6/site-packages/flask/app.py", line 1813, in full_dispatch_request
    rv = self.dispatch_request()
  File "/home/lya/doc/new_flasky/venv/lib/python3.6/site-packages/flask/app.py", line 1791, in dispatch_request
    self.raise_routing_exception(req)
  File "/home/lya/doc/new_flasky/venv/lib/python3.6/site-packages/flask/app.py", line 1774, in raise_routing_exception
    raise request.routing_exception
  File "/home/lya/doc/new_flasky/venv/lib/python3.6/site-packages/flask/ctx.py", line 336, in match_request
    self.url_adapter.match(return_rule=True)
  File "/home/lya/doc/new_flasky/venv/lib/python3.6/site-packages/werkzeug/routing.py", line 1581, in match
    raise NotFound()
werkzeug.exceptions.NotFound: 404 Not Found: The requested URL was not found on the server.  If you entered the URL manually please check your spelling and try again.

During handling of the above exception, another exception occurred:

Traceback (most recent call last):
  File "/home/lya/doc/new_flasky/venv/lib/python3.6/site-packages/flask/app.py", line 2292, in wsgi_app
    response = self.full_dispatch_request()
  File "/home/lya/doc/new_flasky/venv/lib/python3.6/site-packages/flask/app.py", line 1815, in full_dispatch_request
    rv = self.handle_user_exception(e)
  File "/home/lya/doc/new_flasky/venv/lib/python3.6/site-packages/flask/app.py", line 1713, in handle_user_exception
    return self.handle_http_exception(e)
  File "/home/lya/doc/new_flasky/venv/lib/python3.6/site-packages/flask/app.py", line 1644, in handle_http_exception
    return handler(e)
  File "/home/lya/doc/new_flasky/app/main/errors.py", line 16, in page_not_found
    return render_template('404.html'), 404
  File "/home/lya/doc/new_flasky/venv/lib/python3.6/site-packages/flask/templating.py", line 135, in render_template
    context, ctx.app)
  File "/home/lya/doc/new_flasky/venv/lib/python3.6/site-packages/flask/templating.py", line 117, in _render
    rv = template.render(context)
  File "/home/lya/doc/new_flasky/venv/lib/python3.6/site-packages/jinja2/asyncsupport.py", line 76, in render
    return original_render(self, *args, **kwargs)
  File "/home/lya/doc/new_flasky/venv/lib/python3.6/site-packages/jinja2/environment.py", line 1008, in render
    return self.environment.handle_exception(exc_info, True)
  File "/home/lya/doc/new_flasky/venv/lib/python3.6/site-packages/jinja2/environment.py", line 780, in handle_exception
    reraise(exc_type, exc_value, tb)
  File "/home/lya/doc/new_flasky/venv/lib/python3.6/site-packages/jinja2/_compat.py", line 37, in reraise
    raise value.with_traceback(tb)
  File "/home/lya/doc/new_flasky/app/templates/base.html", line 67, in template
    {% endblock %}
  File "/home/lya/doc/new_flasky/venv/lib/python3.6/site-packages/jinja2/environment.py", line 1005, in render
    return concat(self.root_render_func(self.new_context(vars)))
  File "/home/lya/doc/new_flasky/app/templates/404.html", line 1, in top-level template code
    {% extends "base.html" %}
  File "/home/lya/doc/new_flasky/venv/lib/python3.6/site-packages/jinja2/environment.py", line 780, in handle_exception
    reraise(exc_type, exc_value, tb)
  File "/home/lya/doc/new_flasky/venv/lib/python3.6/site-packages/jinja2/_compat.py", line 37, in reraise
    raise value.with_traceback(tb)
  File "/home/lya/doc/new_flasky/app/templates/base.html", line 67, in template
    {% endblock %}
  File "/home/lya/doc/new_flasky/venv/lib/python3.6/site-packages/jinja2/environment.py", line 497, in _parse
    return Parser(self, source, name, encode_filename(filename)).parse()
  File "/home/lya/doc/new_flasky/venv/lib/python3.6/site-packages/jinja2/parser.py", line 901, in parse
    result = nodes.Template(self.subparse(), lineno=1)
  File "/home/lya/doc/new_flasky/venv/lib/python3.6/site-packages/jinja2/parser.py", line 883, in subparse
    rv = self.parse_statement()
  File "/home/lya/doc/new_flasky/venv/lib/python3.6/site-packages/jinja2/parser.py", line 130, in parse_statement
    return getattr(self, 'parse_' + self.stream.current.value)()
  File "/home/lya/doc/new_flasky/venv/lib/python3.6/site-packages/jinja2/parser.py", line 268, in parse_block
    node.body = self.parse_statements(('name:endblock',), drop_needle=True)
  File "/home/lya/doc/new_flasky/venv/lib/python3.6/site-packages/jinja2/parser.py", line 165, in parse_statements
    result = self.subparse(end_tokens)
  File "/home/lya/doc/new_flasky/venv/lib/python3.6/site-packages/jinja2/parser.py", line 883, in subparse
    rv = self.parse_statement()
  File "/home/lya/doc/new_flasky/venv/lib/python3.6/site-packages/jinja2/parser.py", line 130, in parse_statement
    return getattr(self, 'parse_' + self.stream.current.value)()
  File "/home/lya/doc/new_flasky/venv/lib/python3.6/site-packages/jinja2/parser.py", line 213, in parse_if
    'name:endif'))
  File "/home/lya/doc/new_flasky/venv/lib/python3.6/site-packages/jinja2/parser.py", line 165, in parse_statements
    result = self.subparse(end_tokens)
  File "/home/lya/doc/new_flasky/venv/lib/python3.6/site-packages/jinja2/parser.py", line 883, in subparse
    rv = self.parse_statement()
  File "/home/lya/doc/new_flasky/venv/lib/python3.6/site-packages/jinja2/parser.py", line 144, in parse_statement
    self.fail_unknown_tag(token.value, token.lineno)
  File "/home/lya/doc/new_flasky/venv/lib/python3.6/site-packages/jinja2/parser.py", line 97, in fail_unknown_tag
    return self._fail_ut_eof(name, self._end_token_stack, lineno)
  File "/home/lya/doc/new_flasky/venv/lib/python3.6/site-packages/jinja2/parser.py", line 90, in _fail_ut_eof
    self.fail(' '.join(message), lineno)
  File "/home/lya/doc/new_flasky/venv/lib/python3.6/site-packages/jinja2/parser.py", line 59, in fail
    raise exc(msg, lineno, self.name, self.filename)
jinja2.exceptions.TemplateSyntaxError: Encountered unknown tag 'endblock'. You probably made a nesting mistake. Jinja is expecting this tag, but currently looking for 'elif' or 'else' or 'endif'. The innermost block that needs to be closed is 'if'.
[2018-10-02 17:45:08,672] ERROR in app: Exception on /moderate/ [GET]
Traceback (most recent call last):
  File "/home/lya/doc/new_flasky/venv/lib/python3.6/site-packages/flask/app.py", line 2292, in wsgi_app
    response = self.full_dispatch_request()
  File "/home/lya/doc/new_flasky/venv/lib/python3.6/site-packages/flask/app.py", line 1815, in full_dispatch_request
    rv = self.handle_user_exception(e)
  File "/home/lya/doc/new_flasky/venv/lib/python3.6/site-packages/flask/app.py", line 1718, in handle_user_exception
    reraise(exc_type, exc_value, tb)
  File "/home/lya/doc/new_flasky/venv/lib/python3.6/site-packages/flask/_compat.py", line 35, in reraise
    raise value
  File "/home/lya/doc/new_flasky/venv/lib/python3.6/site-packages/flask/app.py", line 1813, in full_dispatch_request
    rv = self.dispatch_request()
  File "/home/lya/doc/new_flasky/venv/lib/python3.6/site-packages/flask/app.py", line 1799, in dispatch_request
    return self.view_functions[rule.endpoint](**req.view_args)
  File "/home/lya/doc/new_flasky/venv/lib/python3.6/site-packages/flask_login/utils.py", line 261, in decorated_view
    return func(*args, **kwargs)
  File "/home/lya/doc/new_flasky/app/decorators.py", line 13, in decorated_function
    return f(*args, **kwargs)
  File "/home/lya/doc/new_flasky/app/main/views.py", line 276, in moderate
    return render_template('moderate.html', comments=comments, pagination=pagination, page=page)
  File "/home/lya/doc/new_flasky/venv/lib/python3.6/site-packages/flask/templating.py", line 135, in render_template
    context, ctx.app)
  File "/home/lya/doc/new_flasky/venv/lib/python3.6/site-packages/flask/templating.py", line 117, in _render
    rv = template.render(context)
  File "/home/lya/doc/new_flasky/venv/lib/python3.6/site-packages/jinja2/asyncsupport.py", line 76, in render
    return original_render(self, *args, **kwargs)
  File "/home/lya/doc/new_flasky/venv/lib/python3.6/site-packages/jinja2/environment.py", line 1008, in render
    return self.environment.handle_exception(exc_info, True)
  File "/home/lya/doc/new_flasky/venv/lib/python3.6/site-packages/jinja2/environment.py", line 780, in handle_exception
    reraise(exc_type, exc_value, tb)
  File "/home/lya/doc/new_flasky/venv/lib/python3.6/site-packages/jinja2/_compat.py", line 37, in reraise
    raise value.with_traceback(tb)
  File "/home/lya/doc/new_flasky/app/templates/base.html", line 67, in template
    {% endblock %}
  File "/home/lya/doc/new_flasky/venv/lib/python3.6/site-packages/jinja2/environment.py", line 1005, in render
    return concat(self.root_render_func(self.new_context(vars)))
  File "/home/lya/doc/new_flasky/app/templates/moderate.html", line 1, in top-level template code
    {% extends 'base.html' %}
  File "/home/lya/doc/new_flasky/venv/lib/python3.6/site-packages/jinja2/environment.py", line 780, in handle_exception
    reraise(exc_type, exc_value, tb)
  File "/home/lya/doc/new_flasky/venv/lib/python3.6/site-packages/jinja2/_compat.py", line 37, in reraise
    raise value.with_traceback(tb)
  File "/home/lya/doc/new_flasky/app/templates/base.html", line 67, in template
    {% endblock %}
  File "/home/lya/doc/new_flasky/venv/lib/python3.6/site-packages/jinja2/environment.py", line 497, in _parse
    return Parser(self, source, name, encode_filename(filename)).parse()
  File "/home/lya/doc/new_flasky/venv/lib/python3.6/site-packages/jinja2/parser.py", line 901, in parse
    result = nodes.Template(self.subparse(), lineno=1)
  File "/home/lya/doc/new_flasky/venv/lib/python3.6/site-packages/jinja2/parser.py", line 883, in subparse
    rv = self.parse_statement()
  File "/home/lya/doc/new_flasky/venv/lib/python3.6/site-packages/jinja2/parser.py", line 130, in parse_statement
    return getattr(self, 'parse_' + self.stream.current.value)()
  File "/home/lya/doc/new_flasky/venv/lib/python3.6/site-packages/jinja2/parser.py", line 268, in parse_block
    node.body = self.parse_statements(('name:endblock',), drop_needle=True)
  File "/home/lya/doc/new_flasky/venv/lib/python3.6/site-packages/jinja2/parser.py", line 165, in parse_statements
    result = self.subparse(end_tokens)
  File "/home/lya/doc/new_flasky/venv/lib/python3.6/site-packages/jinja2/parser.py", line 883, in subparse
    rv = self.parse_statement()
  File "/home/lya/doc/new_flasky/venv/lib/python3.6/site-packages/jinja2/parser.py", line 130, in parse_statement
    return getattr(self, 'parse_' + self.stream.current.value)()
  File "/home/lya/doc/new_flasky/venv/lib/python3.6/site-packages/jinja2/parser.py", line 213, in parse_if
    'name:endif'))
  File "/home/lya/doc/new_flasky/venv/lib/python3.6/site-packages/jinja2/parser.py", line 165, in parse_statements
    result = self.subparse(end_tokens)
  File "/home/lya/doc/new_flasky/venv/lib/python3.6/site-packages/jinja2/parser.py", line 883, in subparse
    rv = self.parse_statement()
  File "/home/lya/doc/new_flasky/venv/lib/python3.6/site-packages/jinja2/parser.py", line 144, in parse_statement
    self.fail_unknown_tag(token.value, token.lineno)
  File "/home/lya/doc/new_flasky/venv/lib/python3.6/site-packages/jinja2/parser.py", line 97, in fail_unknown_tag
    return self._fail_ut_eof(name, self._end_token_stack, lineno)
  File "/home/lya/doc/new_flasky/venv/lib/python3.6/site-packages/jinja2/parser.py", line 90, in _fail_ut_eof
    self.fail(' '.join(message), lineno)
  File "/home/lya/doc/new_flasky/venv/lib/python3.6/site-packages/jinja2/parser.py", line 59, in fail
    raise exc(msg, lineno, self.name, self.filename)
jinja2.exceptions.TemplateSyntaxError: Encountered unknown tag 'endblock'. You probably made a nesting mistake. Jinja is expecting this tag, but currently looking for 'elif' or 'else' or 'endif'. The innermost block that needs to be closed is 'if'.
[2018-10-02 17:45:09,269] ERROR in app: Exception on /favicon.ico [GET]
Traceback (most recent call last):
  File "/home/lya/doc/new_flasky/venv/lib/python3.6/site-packages/flask/app.py", line 1813, in full_dispatch_request
    rv = self.dispatch_request()
  File "/home/lya/doc/new_flasky/venv/lib/python3.6/site-packages/flask/app.py", line 1791, in dispatch_request
    self.raise_routing_exception(req)
  File "/home/lya/doc/new_flasky/venv/lib/python3.6/site-packages/flask/app.py", line 1774, in raise_routing_exception
    raise request.routing_exception
  File "/home/lya/doc/new_flasky/venv/lib/python3.6/site-packages/flask/ctx.py", line 336, in match_request
    self.url_adapter.match(return_rule=True)
  File "/home/lya/doc/new_flasky/venv/lib/python3.6/site-packages/werkzeug/routing.py", line 1581, in match
    raise NotFound()
werkzeug.exceptions.NotFound: 404 Not Found: The requested URL was not found on the server.  If you entered the URL manually please check your spelling and try again.

During handling of the above exception, another exception occurred:

Traceback (most recent call last):
  File "/home/lya/doc/new_flasky/venv/lib/python3.6/site-packages/flask/app.py", line 2292, in wsgi_app
    response = self.full_dispatch_request()
  File "/home/lya/doc/new_flasky/venv/lib/python3.6/site-packages/flask/app.py", line 1815, in full_dispatch_request
    rv = self.handle_user_exception(e)
  File "/home/lya/doc/new_flasky/venv/lib/python3.6/site-packages/flask/app.py", line 1713, in handle_user_exception
    return self.handle_http_exception(e)
  File "/home/lya/doc/new_flasky/venv/lib/python3.6/site-packages/flask/app.py", line 1644, in handle_http_exception
    return handler(e)
  File "/home/lya/doc/new_flasky/app/main/errors.py", line 16, in page_not_found
    return render_template('404.html'), 404
  File "/home/lya/doc/new_flasky/venv/lib/python3.6/site-packages/flask/templating.py", line 135, in render_template
    context, ctx.app)
  File "/home/lya/doc/new_flasky/venv/lib/python3.6/site-packages/flask/templating.py", line 117, in _render
    rv = template.render(context)
  File "/home/lya/doc/new_flasky/venv/lib/python3.6/site-packages/jinja2/asyncsupport.py", line 76, in render
    return original_render(self, *args, **kwargs)
  File "/home/lya/doc/new_flasky/venv/lib/python3.6/site-packages/jinja2/environment.py", line 1008, in render
    return self.environment.handle_exception(exc_info, True)
  File "/home/lya/doc/new_flasky/venv/lib/python3.6/site-packages/jinja2/environment.py", line 780, in handle_exception
    reraise(exc_type, exc_value, tb)
  File "/home/lya/doc/new_flasky/venv/lib/python3.6/site-packages/jinja2/_compat.py", line 37, in reraise
    raise value.with_traceback(tb)
  File "/home/lya/doc/new_flasky/app/templates/base.html", line 67, in template
    {% endblock %}
  File "/home/lya/doc/new_flasky/venv/lib/python3.6/site-packages/jinja2/environment.py", line 1005, in render
    return concat(self.root_render_func(self.new_context(vars)))
  File "/home/lya/doc/new_flasky/app/templates/404.html", line 1, in top-level template code
    {% extends "base.html" %}
  File "/home/lya/doc/new_flasky/venv/lib/python3.6/site-packages/jinja2/environment.py", line 780, in handle_exception
    reraise(exc_type, exc_value, tb)
  File "/home/lya/doc/new_flasky/venv/lib/python3.6/site-packages/jinja2/_compat.py", line 37, in reraise
    raise value.with_traceback(tb)
  File "/home/lya/doc/new_flasky/app/templates/base.html", line 67, in template
    {% endblock %}
  File "/home/lya/doc/new_flasky/venv/lib/python3.6/site-packages/jinja2/environment.py", line 497, in _parse
    return Parser(self, source, name, encode_filename(filename)).parse()
  File "/home/lya/doc/new_flasky/venv/lib/python3.6/site-packages/jinja2/parser.py", line 901, in parse
    result = nodes.Template(self.subparse(), lineno=1)
  File "/home/lya/doc/new_flasky/venv/lib/python3.6/site-packages/jinja2/parser.py", line 883, in subparse
    rv = self.parse_statement()
  File "/home/lya/doc/new_flasky/venv/lib/python3.6/site-packages/jinja2/parser.py", line 130, in parse_statement
    return getattr(self, 'parse_' + self.stream.current.value)()
  File "/home/lya/doc/new_flasky/venv/lib/python3.6/site-packages/jinja2/parser.py", line 268, in parse_block
    node.body = self.parse_statements(('name:endblock',), drop_needle=True)
  File "/home/lya/doc/new_flasky/venv/lib/python3.6/site-packages/jinja2/parser.py", line 165, in parse_statements
    result = self.subparse(end_tokens)
  File "/home/lya/doc/new_flasky/venv/lib/python3.6/site-packages/jinja2/parser.py", line 883, in subparse
    rv = self.parse_statement()
  File "/home/lya/doc/new_flasky/venv/lib/python3.6/site-packages/jinja2/parser.py", line 130, in parse_statement
    return getattr(self, 'parse_' + self.stream.current.value)()
  File "/home/lya/doc/new_flasky/venv/lib/python3.6/site-packages/jinja2/parser.py", line 213, in parse_if
    'name:endif'))
  File "/home/lya/doc/new_flasky/venv/lib/python3.6/site-packages/jinja2/parser.py", line 165, in parse_statements
    result = self.subparse(end_tokens)
  File "/home/lya/doc/new_flasky/venv/lib/python3.6/site-packages/jinja2/parser.py", line 883, in subparse
    rv = self.parse_statement()
  File "/home/lya/doc/new_flasky/venv/lib/python3.6/site-packages/jinja2/parser.py", line 144, in parse_statement
    self.fail_unknown_tag(token.value, token.lineno)
  File "/home/lya/doc/new_flasky/venv/lib/python3.6/site-packages/jinja2/parser.py", line 97, in fail_unknown_tag
    return self._fail_ut_eof(name, self._end_token_stack, lineno)
  File "/home/lya/doc/new_flasky/venv/lib/python3.6/site-packages/jinja2/parser.py", line 90, in _fail_ut_eof
    self.fail(' '.join(message), lineno)
  File "/home/lya/doc/new_flasky/venv/lib/python3.6/site-packages/jinja2/parser.py", line 59, in fail
    raise exc(msg, lineno, self.name, self.filename)
jinja2.exceptions.TemplateSyntaxError: Encountered unknown tag 'endblock'. You probably made a nesting mistake. Jinja is expecting this tag, but currently looking for 'elif' or 'else' or 'endif'. The innermost block that needs to be closed is 'if'.
[2018-10-02 17:45:18,726] ERROR in app: Exception on /moderate/ [GET]
Traceback (most recent call last):
  File "/home/lya/doc/new_flasky/venv/lib/python3.6/site-packages/flask/app.py", line 2292, in wsgi_app
    response = self.full_dispatch_request()
  File "/home/lya/doc/new_flasky/venv/lib/python3.6/site-packages/flask/app.py", line 1815, in full_dispatch_request
    rv = self.handle_user_exception(e)
  File "/home/lya/doc/new_flasky/venv/lib/python3.6/site-packages/flask/app.py", line 1718, in handle_user_exception
    reraise(exc_type, exc_value, tb)
  File "/home/lya/doc/new_flasky/venv/lib/python3.6/site-packages/flask/_compat.py", line 35, in reraise
    raise value
  File "/home/lya/doc/new_flasky/venv/lib/python3.6/site-packages/flask/app.py", line 1813, in full_dispatch_request
    rv = self.dispatch_request()
  File "/home/lya/doc/new_flasky/venv/lib/python3.6/site-packages/flask/app.py", line 1799, in dispatch_request
    return self.view_functions[rule.endpoint](**req.view_args)
  File "/home/lya/doc/new_flasky/venv/lib/python3.6/site-packages/flask_login/utils.py", line 261, in decorated_view
    return func(*args, **kwargs)
  File "/home/lya/doc/new_flasky/app/decorators.py", line 13, in decorated_function
    return f(*args, **kwargs)
  File "/home/lya/doc/new_flasky/app/main/views.py", line 276, in moderate
    return render_template('moderate.html', comments=comments, pagination=pagination, page=page)
  File "/home/lya/doc/new_flasky/venv/lib/python3.6/site-packages/flask/templating.py", line 135, in render_template
    context, ctx.app)
  File "/home/lya/doc/new_flasky/venv/lib/python3.6/site-packages/flask/templating.py", line 117, in _render
    rv = template.render(context)
  File "/home/lya/doc/new_flasky/venv/lib/python3.6/site-packages/jinja2/asyncsupport.py", line 76, in render
    return original_render(self, *args, **kwargs)
  File "/home/lya/doc/new_flasky/venv/lib/python3.6/site-packages/jinja2/environment.py", line 1008, in render
    return self.environment.handle_exception(exc_info, True)
  File "/home/lya/doc/new_flasky/venv/lib/python3.6/site-packages/jinja2/environment.py", line 780, in handle_exception
    reraise(exc_type, exc_value, tb)
  File "/home/lya/doc/new_flasky/venv/lib/python3.6/site-packages/jinja2/_compat.py", line 37, in reraise
    raise value.with_traceback(tb)
  File "/home/lya/doc/new_flasky/app/templates/base.html", line 67, in template
    {% endblock %}
  File "/home/lya/doc/new_flasky/venv/lib/python3.6/site-packages/jinja2/environment.py", line 1005, in render
    return concat(self.root_render_func(self.new_context(vars)))
  File "/home/lya/doc/new_flasky/app/templates/moderate.html", line 1, in top-level template code
    {% extends 'base.html' %}
  File "/home/lya/doc/new_flasky/venv/lib/python3.6/site-packages/jinja2/environment.py", line 780, in handle_exception
    reraise(exc_type, exc_value, tb)
  File "/home/lya/doc/new_flasky/venv/lib/python3.6/site-packages/jinja2/_compat.py", line 37, in reraise
    raise value.with_traceback(tb)
  File "/home/lya/doc/new_flasky/app/templates/base.html", line 67, in template
    {% endblock %}
  File "/home/lya/doc/new_flasky/venv/lib/python3.6/site-packages/jinja2/environment.py", line 497, in _parse
    return Parser(self, source, name, encode_filename(filename)).parse()
  File "/home/lya/doc/new_flasky/venv/lib/python3.6/site-packages/jinja2/parser.py", line 901, in parse
    result = nodes.Template(self.subparse(), lineno=1)
  File "/home/lya/doc/new_flasky/venv/lib/python3.6/site-packages/jinja2/parser.py", line 883, in subparse
    rv = self.parse_statement()
  File "/home/lya/doc/new_flasky/venv/lib/python3.6/site-packages/jinja2/parser.py", line 130, in parse_statement
    return getattr(self, 'parse_' + self.stream.current.value)()
  File "/home/lya/doc/new_flasky/venv/lib/python3.6/site-packages/jinja2/parser.py", line 268, in parse_block
    node.body = self.parse_statements(('name:endblock',), drop_needle=True)
  File "/home/lya/doc/new_flasky/venv/lib/python3.6/site-packages/jinja2/parser.py", line 165, in parse_statements
    result = self.subparse(end_tokens)
  File "/home/lya/doc/new_flasky/venv/lib/python3.6/site-packages/jinja2/parser.py", line 883, in subparse
    rv = self.parse_statement()
  File "/home/lya/doc/new_flasky/venv/lib/python3.6/site-packages/jinja2/parser.py", line 130, in parse_statement
    return getattr(self, 'parse_' + self.stream.current.value)()
  File "/home/lya/doc/new_flasky/venv/lib/python3.6/site-packages/jinja2/parser.py", line 213, in parse_if
    'name:endif'))
  File "/home/lya/doc/new_flasky/venv/lib/python3.6/site-packages/jinja2/parser.py", line 165, in parse_statements
    result = self.subparse(end_tokens)
  File "/home/lya/doc/new_flasky/venv/lib/python3.6/site-packages/jinja2/parser.py", line 883, in subparse
    rv = self.parse_statement()
  File "/home/lya/doc/new_flasky/venv/lib/python3.6/site-packages/jinja2/parser.py", line 144, in parse_statement
    self.fail_unknown_tag(token.value, token.lineno)
  File "/home/lya/doc/new_flasky/venv/lib/python3.6/site-packages/jinja2/parser.py", line 97, in fail_unknown_tag
    return self._fail_ut_eof(name, self._end_token_stack, lineno)
  File "/home/lya/doc/new_flasky/venv/lib/python3.6/site-packages/jinja2/parser.py", line 90, in _fail_ut_eof
    self.fail(' '.join(message), lineno)
  File "/home/lya/doc/new_flasky/venv/lib/python3.6/site-packages/jinja2/parser.py", line 59, in fail
    raise exc(msg, lineno, self.name, self.filename)
jinja2.exceptions.TemplateSyntaxError: Encountered unknown tag 'endblock'. You probably made a nesting mistake. Jinja is expecting this tag, but currently looking for 'elif' or 'else' or 'endif'. The innermost block that needs to be closed is 'if'.
[2018-10-02 17:45:19,302] ERROR in app: Exception on /favicon.ico [GET]
Traceback (most recent call last):
  File "/home/lya/doc/new_flasky/venv/lib/python3.6/site-packages/flask/app.py", line 1813, in full_dispatch_request
    rv = self.dispatch_request()
  File "/home/lya/doc/new_flasky/venv/lib/python3.6/site-packages/flask/app.py", line 1791, in dispatch_request
    self.raise_routing_exception(req)
  File "/home/lya/doc/new_flasky/venv/lib/python3.6/site-packages/flask/app.py", line 1774, in raise_routing_exception
    raise request.routing_exception
  File "/home/lya/doc/new_flasky/venv/lib/python3.6/site-packages/flask/ctx.py", line 336, in match_request
    self.url_adapter.match(return_rule=True)
  File "/home/lya/doc/new_flasky/venv/lib/python3.6/site-packages/werkzeug/routing.py", line 1581, in match
    raise NotFound()
werkzeug.exceptions.NotFound: 404 Not Found: The requested URL was not found on the server.  If you entered the URL manually please check your spelling and try again.

During handling of the above exception, another exception occurred:

Traceback (most recent call last):
  File "/home/lya/doc/new_flasky/venv/lib/python3.6/site-packages/flask/app.py", line 2292, in wsgi_app
    response = self.full_dispatch_request()
  File "/home/lya/doc/new_flasky/venv/lib/python3.6/site-packages/flask/app.py", line 1815, in full_dispatch_request
    rv = self.handle_user_exception(e)
  File "/home/lya/doc/new_flasky/venv/lib/python3.6/site-packages/flask/app.py", line 1713, in handle_user_exception
    return self.handle_http_exception(e)
  File "/home/lya/doc/new_flasky/venv/lib/python3.6/site-packages/flask/app.py", line 1644, in handle_http_exception
    return handler(e)
  File "/home/lya/doc/new_flasky/app/main/errors.py", line 16, in page_not_found
    return render_template('404.html'), 404
  File "/home/lya/doc/new_flasky/venv/lib/python3.6/site-packages/flask/templating.py", line 135, in render_template
    context, ctx.app)
  File "/home/lya/doc/new_flasky/venv/lib/python3.6/site-packages/flask/templating.py", line 117, in _render
    rv = template.render(context)
  File "/home/lya/doc/new_flasky/venv/lib/python3.6/site-packages/jinja2/asyncsupport.py", line 76, in render
    return original_render(self, *args, **kwargs)
  File "/home/lya/doc/new_flasky/venv/lib/python3.6/site-packages/jinja2/environment.py", line 1008, in render
    return self.environment.handle_exception(exc_info, True)
  File "/home/lya/doc/new_flasky/venv/lib/python3.6/site-packages/jinja2/environment.py", line 780, in handle_exception
    reraise(exc_type, exc_value, tb)
  File "/home/lya/doc/new_flasky/venv/lib/python3.6/site-packages/jinja2/_compat.py", line 37, in reraise
    raise value.with_traceback(tb)
  File "/home/lya/doc/new_flasky/app/templates/base.html", line 67, in template
    {% endblock %}
  File "/home/lya/doc/new_flasky/venv/lib/python3.6/site-packages/jinja2/environment.py", line 1005, in render
    return concat(self.root_render_func(self.new_context(vars)))
  File "/home/lya/doc/new_flasky/app/templates/404.html", line 1, in top-level template code
    {% extends "base.html" %}
  File "/home/lya/doc/new_flasky/venv/lib/python3.6/site-packages/jinja2/environment.py", line 780, in handle_exception
    reraise(exc_type, exc_value, tb)
  File "/home/lya/doc/new_flasky/venv/lib/python3.6/site-packages/jinja2/_compat.py", line 37, in reraise
    raise value.with_traceback(tb)
  File "/home/lya/doc/new_flasky/app/templates/base.html", line 67, in template
    {% endblock %}
  File "/home/lya/doc/new_flasky/venv/lib/python3.6/site-packages/jinja2/environment.py", line 497, in _parse
    return Parser(self, source, name, encode_filename(filename)).parse()
  File "/home/lya/doc/new_flasky/venv/lib/python3.6/site-packages/jinja2/parser.py", line 901, in parse
    result = nodes.Template(self.subparse(), lineno=1)
  File "/home/lya/doc/new_flasky/venv/lib/python3.6/site-packages/jinja2/parser.py", line 883, in subparse
    rv = self.parse_statement()
  File "/home/lya/doc/new_flasky/venv/lib/python3.6/site-packages/jinja2/parser.py", line 130, in parse_statement
    return getattr(self, 'parse_' + self.stream.current.value)()
  File "/home/lya/doc/new_flasky/venv/lib/python3.6/site-packages/jinja2/parser.py", line 268, in parse_block
    node.body = self.parse_statements(('name:endblock',), drop_needle=True)
  File "/home/lya/doc/new_flasky/venv/lib/python3.6/site-packages/jinja2/parser.py", line 165, in parse_statements
    result = self.subparse(end_tokens)
  File "/home/lya/doc/new_flasky/venv/lib/python3.6/site-packages/jinja2/parser.py", line 883, in subparse
    rv = self.parse_statement()
  File "/home/lya/doc/new_flasky/venv/lib/python3.6/site-packages/jinja2/parser.py", line 130, in parse_statement
    return getattr(self, 'parse_' + self.stream.current.value)()
  File "/home/lya/doc/new_flasky/venv/lib/python3.6/site-packages/jinja2/parser.py", line 213, in parse_if
    'name:endif'))
  File "/home/lya/doc/new_flasky/venv/lib/python3.6/site-packages/jinja2/parser.py", line 165, in parse_statements
    result = self.subparse(end_tokens)
  File "/home/lya/doc/new_flasky/venv/lib/python3.6/site-packages/jinja2/parser.py", line 883, in subparse
    rv = self.parse_statement()
  File "/home/lya/doc/new_flasky/venv/lib/python3.6/site-packages/jinja2/parser.py", line 144, in parse_statement
    self.fail_unknown_tag(token.value, token.lineno)
  File "/home/lya/doc/new_flasky/venv/lib/python3.6/site-packages/jinja2/parser.py", line 97, in fail_unknown_tag
    return self._fail_ut_eof(name, self._end_token_stack, lineno)
  File "/home/lya/doc/new_flasky/venv/lib/python3.6/site-packages/jinja2/parser.py", line 90, in _fail_ut_eof
    self.fail(' '.join(message), lineno)
  File "/home/lya/doc/new_flasky/venv/lib/python3.6/site-packages/jinja2/parser.py", line 59, in fail
    raise exc(msg, lineno, self.name, self.filename)
jinja2.exceptions.TemplateSyntaxError: Encountered unknown tag 'endblock'. You probably made a nesting mistake. Jinja is expecting this tag, but currently looking for 'elif' or 'else' or 'endif'. The innermost block that needs to be closed is 'if'.
